2016-04-14 11:41:24,388 - config (7050) - WARNING - Couldn't find logger 'LOG' in '<module '__main__' (built-in)>'
2016-04-14 11:41:24,388 - config (7050) - WARNING - Couldn't find logger 'LOG' in '<module 'stagyy' from '/home/robert/lib/python/stagyy-2015.11.30.12.51-py2.7.egg/stagyy/__init__.pyc'>'
2016-04-14 11:41:24,389 - config (7050) - ERROR - Error configurintg log: youtube.LOG
Traceback (most recent call last):
  File "/var/wallander/conf/config.py", line 69, in add_logger
    mod=importlib.import_module(mod)
  File "/usr/lib/python2.7/importlib/__init__.py", line 37, in import_module
    __import__(name)
  File "/var/wallander/data_providers/youtube/__init__.py", line 8, in <module>
    class DataProvider(wallander.BaseDataProvider):
AttributeError: 'module' object has no attribute 'BaseDataProvider'
2016-04-14 11:43:02,691 - config (7076) - WARNING - Couldn't find logger 'LOG' in '<module '__main__' (built-in)>'
2016-04-14 11:43:02,691 - config (7076) - WARNING - Couldn't find logger 'LOG' in '<module 'stagyy' from '/home/robert/lib/python/stagyy-2015.11.30.12.51-py2.7.egg/stagyy/__init__.pyc'>'
2016-04-14 11:43:02,692 - config (7076) - ERROR - Error configurintg log: youtube.LOG
Traceback (most recent call last):
  File "/var/wallander/conf/config.py", line 69, in add_logger
    mod=importlib.import_module(mod)
  File "/usr/lib/python2.7/importlib/__init__.py", line 37, in import_module
    __import__(name)
  File "/var/wallander/data_providers/youtube/__init__.py", line 8, in <module>
    class DataProvider(wallander.BaseDataProvider):
AttributeError: 'module' object has no attribute 'BaseDataProvider'
2016-04-14 11:49:01,963 - config (7202) - WARNING - Couldn't find logger 'LOG' in '<module '__main__' (built-in)>'
2016-04-14 11:49:01,963 - config (7202) - WARNING - Couldn't find logger 'LOG' in '<module 'stagyy' from '/home/robert/lib/python/stagyy-2015.11.30.12.51-py2.7.egg/stagyy/__init__.pyc'>'
2016-04-14 11:49:01,964 - config (7202) - ERROR - Error configurintg log: youtube.LOG
Traceback (most recent call last):
  File "/var/wallander/conf/config.py", line 69, in add_logger
    mod=importlib.import_module(mod)
  File "/usr/lib/python2.7/importlib/__init__.py", line 37, in import_module
    __import__(name)
  File "/var/wallander/data_providers/youtube/__init__.py", line 8, in <module>
    class DataProvider(wallander.BaseDataProvider):
AttributeError: 'module' object has no attribute 'BaseDataProvider'
2016-04-14 11:49:10,458 - wallander.application (7202) - DEBUG - REQUEST_URI: /wallander/wallander/
2016-04-14 11:49:10,458 - wallander.application (7202) - DEBUG - REQUEST_URI: /wallander/wallander/
2016-04-14 11:49:10,459 - wallander.application (7202) - ERROR - Exception processing request
Traceback (most recent call last):
  File "/var/wallander/python/wallander/application.py", line 38, in __call__
    uri = environ['REQUEST_URI'] if len(environ['PATH_INFO'])==0 else environ['PATH_INFO']
KeyError: 'PATH_INFO'
2016-04-14 11:49:10,459 - wallander.application (7202) - ERROR - Exception processing request
Traceback (most recent call last):
  File "/var/wallander/python/wallander/application.py", line 38, in __call__
    uri = environ['REQUEST_URI'] if len(environ['PATH_INFO'])==0 else environ['PATH_INFO']
KeyError: 'PATH_INFO'
2016-04-14 11:50:08,726 - config (7234) - WARNING - Couldn't find logger 'LOG' in '<module '__main__' (built-in)>'
2016-04-14 11:50:08,726 - config (7234) - WARNING - Couldn't find logger 'LOG' in '<module 'stagyy' from '/home/robert/lib/python/stagyy-2015.11.30.12.51-py2.7.egg/stagyy/__init__.pyc'>'
2016-04-14 11:50:08,727 - config (7234) - ERROR - Error configurintg log: youtube.LOG
Traceback (most recent call last):
  File "/var/wallander/conf/config.py", line 69, in add_logger
    mod=importlib.import_module(mod)
  File "/usr/lib/python2.7/importlib/__init__.py", line 37, in import_module
    __import__(name)
  File "/var/wallander/data_providers/youtube/__init__.py", line 8, in <module>
    class DataProvider(wallander.BaseDataProvider):
AttributeError: 'module' object has no attribute 'BaseDataProvider'
2016-04-14 11:50:10,640 - wallander.application (7234) - DEBUG - REQUEST_URI: /wallander/wallander/
2016-04-14 11:50:10,640 - wallander.application (7234) - DEBUG - REQUEST_URI: /wallander/wallander/
2016-04-14 11:50:10,640 - wallander.application (7234) - DEBUG - Data provider name: 'wallander'
2016-04-14 11:50:10,640 - wallander.application (7234) - DEBUG - Data provider name: 'wallander'
2016-04-14 11:50:10,640 - wallander.application (7234) - DEBUG - Data provider: None
2016-04-14 11:50:10,640 - wallander.application (7234) - DEBUG - Data provider: None
2016-04-14 11:50:10,640 - wallander.application (7234) - DEBUG - No data provider for wallander
2016-04-14 11:50:10,640 - wallander.application (7234) - DEBUG - No data provider for wallander
2016-04-14 11:54:50,823 - config (7316) - WARNING - Couldn't find logger 'LOG' in '<module '__main__' (built-in)>'
2016-04-14 11:54:50,823 - config (7316) - WARNING - Couldn't find logger 'LOG' in '<module 'stagyy' from '/home/robert/lib/python/stagyy-2015.11.30.12.51-py2.7.egg/stagyy/__init__.pyc'>'
2016-04-14 11:54:50,824 - config (7316) - ERROR - Error configurintg log: youtube.LOG
Traceback (most recent call last):
  File "/var/wallander/conf/config.py", line 71, in add_logger
    mod=importlib.import_module(mod)
  File "/usr/lib/python2.7/importlib/__init__.py", line 37, in import_module
    __import__(name)
  File "/var/wallander/data_providers/youtube/__init__.py", line 8, in <module>
    class DataProvider(wallander.BaseDataProvider):
AttributeError: 'module' object has no attribute 'BaseDataProvider'
2016-04-14 11:55:21,393 - config (7339) - WARNING - Couldn't find logger 'LOG' in '<module '__main__' (built-in)>'
2016-04-14 11:55:21,393 - config (7339) - WARNING - Couldn't find logger 'LOG' in '<module 'stagyy' from '/home/robert/lib/python/stagyy-2015.11.30.12.51-py2.7.egg/stagyy/__init__.pyc'>'
2016-04-14 11:55:21,393 - config (7339) - ERROR - Error configurintg log: youtube.LOG
Traceback (most recent call last):
  File "/var/wallander/conf/config.py", line 71, in add_logger
    mod=importlib.import_module(mod)
  File "/usr/lib/python2.7/importlib/__init__.py", line 37, in import_module
    __import__(name)
  File "/var/wallander/data_providers/youtube/__init__.py", line 8, in <module>
    class DataProvider(wallander.BaseDataProvider):
AttributeError: 'module' object has no attribute 'BaseDataProvider'
2016-04-14 11:56:09,089 - wallander.application (7339) - DEBUG - REQUEST_URI: /wallander/wallander/
2016-04-14 11:56:09,089 - wallander.application (7339) - DEBUG - REQUEST_URI: /wallander/wallander/
2016-04-14 11:56:09,090 - wallander.application (7339) - DEBUG - Data provider name: 'wallander'
2016-04-14 11:56:09,090 - wallander.application (7339) - DEBUG - Data provider name: 'wallander'
2016-04-14 11:56:09,090 - wallander.application (7339) - DEBUG - Data provider: None
2016-04-14 11:56:09,090 - wallander.application (7339) - DEBUG - Data provider: None
2016-04-14 11:56:09,090 - wallander.application (7339) - DEBUG - No data provider for wallander
2016-04-14 11:56:09,090 - wallander.application (7339) - DEBUG - No data provider for wallander
2016-04-14 11:56:45,054 - config (7339) - DEBUG - test
2016-04-14 11:57:39,679 - wallander (7339) - DEBUG - test
2016-04-14 12:08:21,006 - config (7702) - WARNING - Couldn't find logger 'LOG' in '<module '__main__' (built-in)>'
2016-04-14 12:08:21,006 - config (7702) - WARNING - Couldn't find logger 'LOG' in '<module 'stagyy' from '/home/robert/lib/python/stagyy-2015.11.30.12.51-py2.7.egg/stagyy/__init__.pyc'>'
2016-04-14 12:08:21,006 - config (7702) - ERROR - Error configurintg log: youtube.LOG
Traceback (most recent call last):
  File "/var/wallander/conf/config.py", line 66, in add_logger
    mod=importlib.import_module(mod)
  File "/usr/lib/python2.7/importlib/__init__.py", line 37, in import_module
    __import__(name)
  File "/var/wallander/data_providers/youtube/__init__.py", line 8, in <module>
    class DataProvider(wallander.BaseDataProvider):
AttributeError: 'module' object has no attribute 'BaseDataProvider'
2016-04-14 12:08:40,051 - config (7722) - WARNING - Couldn't find logger 'LOG' in '<module '__main__' (built-in)>'
2016-04-14 12:08:40,052 - config (7722) - WARNING - Couldn't find logger 'LOG' in '<module 'stagyy' from '/home/robert/lib/python/stagyy-2015.11.30.12.51-py2.7.egg/stagyy/__init__.pyc'>'
2016-04-14 12:08:40,052 - config (7722) - ERROR - Error configurintg log: youtube.LOG
Traceback (most recent call last):
  File "/var/wallander/conf/config.py", line 66, in add_logger
    mod=importlib.import_module(mod)
  File "/usr/lib/python2.7/importlib/__init__.py", line 37, in import_module
    __import__(name)
  File "/var/wallander/data_providers/youtube/__init__.py", line 8, in <module>
    class DataProvider(wallander.BaseDataProvider):
AttributeError: 'module' object has no attribute 'BaseDataProvider'
2016-04-14 12:10:51,421 - config (7791) - WARNING - Couldn't find logger 'LOG' in '<module '__main__' (built-in)>'
2016-04-14 12:10:51,421 - config (7791) - WARNING - Couldn't find logger 'LOG' in '<module 'stagyy' from '/home/robert/lib/python/stagyy-2015.11.30.12.51-py2.7.egg/stagyy/__init__.pyc'>'
2016-04-14 12:13:21,842 - config (7822) - WARNING - Couldn't find logger 'LOG' in '<module '__main__' (built-in)>'
2016-04-14 12:13:21,842 - config (7822) - WARNING - Couldn't find logger 'LOG' in '<module 'stagyy' from '/home/robert/lib/python/stagyy-2015.11.30.12.51-py2.7.egg/stagyy/__init__.pyc'>'
2016-04-14 12:23:28,869 - config (8063) - WARNING - Couldn't find logger 'LOG' in '<module '__main__' (built-in)>'
2016-04-14 12:23:28,869 - config (8063) - WARNING - Couldn't find logger 'LOG' in '<module 'stagyy' from '/home/robert/lib/python/stagyy-2015.11.30.12.51-py2.7.egg/stagyy/__init__.pyc'>'
2016-04-14 12:26:15,797 - config (8114) - WARNING - Couldn't find logger 'LOG' in '<module '__main__' (built-in)>'
2016-04-14 12:27:24,355 - config (8135) - WARNING - Couldn't find logger 'LOG' in '<module '__main__' (built-in)>'
2016-04-14 12:27:54,721 - config (8152) - WARNING - Couldn't find logger 'LOG' in '<module '__main__' (built-in)>'
2016-04-14 12:28:15,862 - wallander.application (8152) - DEBUG - REQUEST_URI: /wallander
2016-04-14 12:28:15,862 - wallander.application (8152) - DEBUG - REQUEST_URI: /wallander
2016-04-14 12:28:15,862 - wallander.application (8152) - DEBUG - Data provider name: 'wallander'
2016-04-14 12:28:15,862 - wallander.application (8152) - DEBUG - Data provider name: 'wallander'
2016-04-14 12:28:15,863 - wallander.application (8152) - DEBUG - Data provider: None
2016-04-14 12:28:15,863 - wallander.application (8152) - DEBUG - Data provider: None
2016-04-14 12:28:15,863 - wallander.application (8152) - DEBUG - No data provider for wallander
2016-04-14 12:28:15,863 - wallander.application (8152) - DEBUG - No data provider for wallander
2016-04-14 12:28:24,199 - wallander.application (8152) - DEBUG - REQUEST_URI: /wallander/wallander
2016-04-14 12:28:24,199 - wallander.application (8152) - DEBUG - REQUEST_URI: /wallander/wallander
2016-04-14 12:28:24,199 - wallander.application (8152) - DEBUG - Data provider name: 'wallander'
2016-04-14 12:28:24,199 - wallander.application (8152) - DEBUG - Data provider name: 'wallander'
2016-04-14 12:28:24,199 - wallander.application (8152) - DEBUG - Data provider: None
2016-04-14 12:28:24,199 - wallander.application (8152) - DEBUG - Data provider: None
2016-04-14 12:28:24,200 - wallander.application (8152) - DEBUG - No data provider for wallander
2016-04-14 12:28:24,200 - wallander.application (8152) - DEBUG - No data provider for wallander
2016-04-14 12:29:02,287 - wallander.application (8152) - DEBUG - REQUEST_URI: /wallander/
2016-04-14 12:29:02,287 - wallander.application (8152) - DEBUG - REQUEST_URI: /wallander/
2016-04-14 12:29:02,288 - wallander.application (8152) - DEBUG - Data provider name: 'wallander'
2016-04-14 12:29:02,288 - wallander.application (8152) - DEBUG - Data provider name: 'wallander'
2016-04-14 12:29:02,288 - wallander.application (8152) - DEBUG - Data provider: None
2016-04-14 12:29:02,288 - wallander.application (8152) - DEBUG - Data provider: None
2016-04-14 12:29:02,288 - wallander.application (8152) - DEBUG - No data provider for wallander
2016-04-14 12:29:02,288 - wallander.application (8152) - DEBUG - No data provider for wallander
2016-04-14 12:29:39,811 - config (8184) - WARNING - Couldn't find logger 'LOG' in '<module '__main__' (built-in)>'
2016-04-14 12:31:41,274 - config (8227) - WARNING - Couldn't find logger 'LOG' in '<module '__main__' (built-in)>'
2016-04-14 12:31:41,278 - wallander.cache (8227) - DEBUG - CacheInvalidationThread started
2016-04-14 12:31:41,278 - wallander.cache (8227) - DEBUG - CacheInvalidationThread started
2016-04-14 12:31:41,278 - wallander.cache (8227) - DEBUG - Checking cache items...
2016-04-14 12:31:41,278 - wallander.cache (8227) - DEBUG - Checking cache items...
2016-04-14 12:32:31,056 - config (8255) - WARNING - Couldn't find logger 'LOG' in '<module '__main__' (built-in)>'
2016-04-14 12:32:31,060 - wallander.cache (8255) - DEBUG - CacheInvalidationThread started
2016-04-14 12:32:31,060 - wallander.cache (8255) - DEBUG - CacheInvalidationThread started
2016-04-14 12:32:31,060 - wallander.cache (8255) - DEBUG - Checking cache items...
2016-04-14 12:32:31,060 - wallander.cache (8255) - DEBUG - Checking cache items...
2016-04-14 12:33:00,645 - config (8280) - WARNING - Couldn't find logger 'LOG' in '<module '__main__' (built-in)>'
2016-04-14 12:33:00,649 - wallander.cache (8280) - DEBUG - CacheInvalidationThread started
2016-04-14 12:33:00,649 - wallander.cache (8280) - DEBUG - CacheInvalidationThread started
2016-04-14 12:33:00,649 - wallander.cache (8280) - DEBUG - Checking cache items...
2016-04-14 12:33:00,649 - wallander.cache (8280) - DEBUG - Checking cache items...
2016-04-14 12:33:42,174 - config (8303) - WARNING - Couldn't find logger 'LOG' in '<module '__main__' (built-in)>'
2016-04-14 12:33:42,178 - wallander.cache (8303) - DEBUG - CacheInvalidationThread started
2016-04-14 12:33:42,178 - wallander.cache (8303) - DEBUG - CacheInvalidationThread started
2016-04-14 12:33:42,178 - wallander.cache (8303) - DEBUG - Checking cache items...
2016-04-14 12:33:42,178 - wallander.cache (8303) - DEBUG - Checking cache items...
2016-04-14 12:34:10,030 - config (8317) - WARNING - Couldn't find logger 'LOG' in '<module '__main__' (built-in)>'
2016-04-14 12:34:10,033 - wallander.cache (8317) - DEBUG - CacheInvalidationThread started
2016-04-14 12:34:10,033 - wallander.cache (8317) - DEBUG - CacheInvalidationThread started
2016-04-14 12:34:10,033 - wallander.cache (8317) - DEBUG - Checking cache items...
2016-04-14 12:34:10,033 - wallander.cache (8317) - DEBUG - Checking cache items...
2016-04-14 12:38:49,521 - config (8397) - WARNING - Couldn't find logger 'LOG' in '<module '__main__' (built-in)>'
2016-04-14 12:38:49,525 - wallander.cache (8397) - DEBUG - CacheInvalidationThread started
2016-04-14 12:38:49,525 - wallander.cache (8397) - DEBUG - CacheInvalidationThread started
2016-04-14 12:38:49,525 - wallander.cache (8397) - DEBUG - Checking cache items...
2016-04-14 12:38:49,525 - wallander.cache (8397) - DEBUG - Checking cache items...
2016-04-14 12:42:56,114 - config (8552) - WARNING - Couldn't find logger 'LOG' in '<module '__main__' (built-in)>'
2016-04-14 12:42:56,114 - config (8552) - ERROR - Error configurintg log: stagyy.LOG
Traceback (most recent call last):
  File "/var/wallander/conf/config.py", line 73, in add_logger
    mod=importlib.import_module(mod)
  File "/usr/lib/python2.7/importlib/__init__.py", line 37, in import_module
    __import__(name)
  File "/var/wallander/data_providers/stagyy/__init__.py", line 74, in <module>
    class StagYYDataSource(wallander.DataSource):
AttributeError: 'module' object has no attribute 'DataSource'
2016-04-14 12:44:08,100 - config (8582) - WARNING - Couldn't find logger 'LOG' in '<module '__main__' (built-in)>'
2016-04-14 12:44:08,104 - wallander.cache (8582) - DEBUG - CacheInvalidationThread started
2016-04-14 12:44:08,104 - wallander.cache (8582) - DEBUG - CacheInvalidationThread started
2016-04-14 12:44:08,104 - wallander.cache (8582) - DEBUG - Checking cache items...
2016-04-14 12:44:08,104 - wallander.cache (8582) - DEBUG - Checking cache items...
2016-04-14 12:44:17,851 - wallander.application (8582) - DEBUG - REQUEST_URI: /wallander/
2016-04-14 12:44:17,851 - wallander.application (8582) - DEBUG - REQUEST_URI: /wallander/
2016-04-14 12:44:17,852 - wallander.application (8582) - DEBUG - Data provider name: 'wallander'
2016-04-14 12:44:17,852 - wallander.application (8582) - DEBUG - Data provider name: 'wallander'
2016-04-14 12:44:17,853 - wallander.application (8582) - DEBUG - Data provider: None
2016-04-14 12:44:17,853 - wallander.application (8582) - DEBUG - Data provider: None
2016-04-14 12:44:17,853 - wallander.application (8582) - DEBUG - No data provider for wallander
2016-04-14 12:44:17,853 - wallander.application (8582) - DEBUG - No data provider for wallander
2016-04-14 12:44:29,694 - wallander.application (8582) - DEBUG - REQUEST_URI: /
2016-04-14 12:44:29,694 - wallander.application (8582) - DEBUG - REQUEST_URI: /
2016-04-14 12:44:29,695 - wallander.application (8582) - DEBUG - Data provider name: ''
2016-04-14 12:44:29,695 - wallander.application (8582) - DEBUG - Data provider name: ''
2016-04-14 12:44:29,696 - wallander.application (8582) - DEBUG - Data provider: <function dp_provider_response at 0x7faecb551c80>
2016-04-14 12:44:29,696 - wallander.application (8582) - DEBUG - Data provider: <function dp_provider_response at 0x7faecb551c80>
2016-04-14 12:44:35,726 - wallander.application (8582) - DEBUG - REQUEST_URI: /stagyy/
2016-04-14 12:44:35,726 - wallander.application (8582) - DEBUG - REQUEST_URI: /stagyy/
2016-04-14 12:44:35,726 - wallander.application (8582) - DEBUG - Data provider name: 'stagyy'
2016-04-14 12:44:35,726 - wallander.application (8582) - DEBUG - Data provider name: 'stagyy'
2016-04-14 12:44:35,727 - wallander.application (8582) - DEBUG - Data provider: <stagyy.DataProvider object at 0x7faecb554310>
2016-04-14 12:44:35,727 - wallander.application (8582) - DEBUG - Data provider: <stagyy.DataProvider object at 0x7faecb554310>
2016-04-14 12:44:35,727 - wallander.data_providers (8582) - DEBUG - Checking path: []
2016-04-14 12:44:35,727 - wallander.data_providers (8582) - DEBUG - Checking path: []
2016-04-14 12:44:35,728 - stagyy (8582) - DEBUG - Checking path: /var/wallander/data/stagyy
2016-04-14 12:44:35,728 - wallander.application (8582) - ERROR - Exception processing request
Traceback (most recent call last):
  File "/var/wallander/python/wallander/application.py", line 45, in __call__
    return dp(environ,start_response,path)
  File "/var/wallander/python/wallander/data_providers.py", line 47, in __call__
    result=self.call(environ,start_response,path)
  File "/var/wallander/data_providers/stagyy/__init__.py", line 47, in call
    response=wallander.data_providers.Folder(fname)
AttributeError: 'module' object has no attribute 'Folder'
2016-04-14 12:44:35,728 - wallander.application (8582) - ERROR - Exception processing request
Traceback (most recent call last):
  File "/var/wallander/python/wallander/application.py", line 45, in __call__
    return dp(environ,start_response,path)
  File "/var/wallander/python/wallander/data_providers.py", line 47, in __call__
    result=self.call(environ,start_response,path)
  File "/var/wallander/data_providers/stagyy/__init__.py", line 47, in call
    response=wallander.data_providers.Folder(fname)
AttributeError: 'module' object has no attribute 'Folder'
2016-04-14 12:49:08,203 - wallander.cache (8582) - DEBUG - Checking cache items...
2016-04-14 12:49:08,203 - wallander.cache (8582) - DEBUG - Checking cache items...
2016-04-14 12:54:08,304 - wallander.cache (8582) - DEBUG - Checking cache items...
2016-04-14 12:54:08,304 - wallander.cache (8582) - DEBUG - Checking cache items...
2016-04-14 12:59:08,392 - wallander.cache (8582) - DEBUG - Checking cache items...
2016-04-14 12:59:08,392 - wallander.cache (8582) - DEBUG - Checking cache items...
2016-04-14 13:00:41,823 - config (8882) - WARNING - Couldn't find logger 'LOG' in '<module '__main__' (built-in)>'
2016-04-14 13:00:41,824 - config (8882) - ERROR - Error configurintg log: stagyy.LOG
Traceback (most recent call last):
  File "/var/wallander/conf/config.py", line 73, in add_logger
    mod=importlib.import_module(mod)
  File "/usr/lib/python2.7/importlib/__init__.py", line 37, in import_module
    __import__(name)
  File "/var/wallander/data_providers/stagyy/__init__.py", line 9, in <module>
    LOG=logging.getLogager(__name__)
AttributeError: 'module' object has no attribute 'getLogager'
2016-04-14 13:01:11,452 - config (8898) - WARNING - Couldn't find logger 'LOG' in '<module '__main__' (built-in)>'
2016-04-14 13:01:15,555 - wallander.application (8898) - DEBUG - REQUEST_URI: /stagyy/
2016-04-14 13:01:15,555 - wallander.application (8898) - DEBUG - REQUEST_URI: /stagyy/
2016-04-14 13:01:15,557 - wallander.application (8898) - DEBUG - Data provider name: 'stagyy'
2016-04-14 13:01:15,557 - wallander.application (8898) - DEBUG - Data provider name: 'stagyy'
2016-04-14 13:01:15,557 - wallander.application (8898) - DEBUG - Data provider: <stagyy.DataProvider object at 0x7f23600237d0>
2016-04-14 13:01:15,557 - wallander.application (8898) - DEBUG - Data provider: <stagyy.DataProvider object at 0x7f23600237d0>
2016-04-14 13:01:15,558 - wallander.data_providers (8898) - DEBUG - Checking path: []
2016-04-14 13:01:15,558 - wallander.data_providers (8898) - DEBUG - Checking path: []
2016-04-14 13:01:15,558 - stagyy (8898) - DEBUG - Checking path: /var/wallander/data/stagyy
2016-04-14 13:01:15,558 - wallander.application (8898) - ERROR - Exception processing request
Traceback (most recent call last):
  File "/var/wallander/python/wallander/application.py", line 45, in __call__
    return dp(environ,start_response,path)
  File "/var/wallander/python/wallander/data_providers.py", line 47, in __call__
    result=self.call(environ,start_response,path)
  File "/var/wallander/data_providers/stagyy/__init__.py", line 48, in call
    response=wallander.data_providers.Folder(fname)
AttributeError: 'module' object has no attribute 'Folder'
2016-04-14 13:01:15,558 - wallander.application (8898) - ERROR - Exception processing request
Traceback (most recent call last):
  File "/var/wallander/python/wallander/application.py", line 45, in __call__
    return dp(environ,start_response,path)
  File "/var/wallander/python/wallander/data_providers.py", line 47, in __call__
    result=self.call(environ,start_response,path)
  File "/var/wallander/data_providers/stagyy/__init__.py", line 48, in call
    response=wallander.data_providers.Folder(fname)
AttributeError: 'module' object has no attribute 'Folder'
2016-04-14 13:01:51,434 - wallander.application (8898) - DEBUG - REQUEST_URI: /stagyy/
2016-04-14 13:01:51,434 - wallander.application (8898) - DEBUG - REQUEST_URI: /stagyy/
2016-04-14 13:01:51,435 - wallander.application (8898) - DEBUG - Data provider name: 'stagyy'
2016-04-14 13:01:51,435 - wallander.application (8898) - DEBUG - Data provider name: 'stagyy'
2016-04-14 13:01:51,435 - wallander.application (8898) - DEBUG - Data provider: <stagyy.DataProvider object at 0x7f23600237d0>
2016-04-14 13:01:51,435 - wallander.application (8898) - DEBUG - Data provider: <stagyy.DataProvider object at 0x7f23600237d0>
2016-04-14 13:01:51,436 - wallander.data_providers (8898) - DEBUG - Checking path: []
2016-04-14 13:01:51,436 - wallander.data_providers (8898) - DEBUG - Checking path: []
2016-04-14 13:01:51,436 - stagyy (8898) - DEBUG - Checking path: /var/wallander/data/stagyy
2016-04-14 13:01:51,436 - wallander.application (8898) - ERROR - Exception processing request
Traceback (most recent call last):
  File "/var/wallander/python/wallander/application.py", line 45, in __call__
    return dp(environ,start_response,path)
  File "/var/wallander/python/wallander/data_providers.py", line 47, in __call__
    result=self.call(environ,start_response,path)
  File "/var/wallander/data_providers/stagyy/__init__.py", line 48, in call
    response=H5Folder(fname)
AttributeError: 'module' object has no attribute 'Folder'
2016-04-14 13:01:51,436 - wallander.application (8898) - ERROR - Exception processing request
Traceback (most recent call last):
  File "/var/wallander/python/wallander/application.py", line 45, in __call__
    return dp(environ,start_response,path)
  File "/var/wallander/python/wallander/data_providers.py", line 47, in __call__
    result=self.call(environ,start_response,path)
  File "/var/wallander/data_providers/stagyy/__init__.py", line 48, in call
    response=H5Folder(fname)
AttributeError: 'module' object has no attribute 'Folder'
2016-04-14 13:01:55,195 - config (8923) - WARNING - Couldn't find logger 'LOG' in '<module '__main__' (built-in)>'
2016-04-14 13:01:55,198 - wallander.cache (8923) - DEBUG - CacheInvalidationThread started
2016-04-14 13:01:55,198 - wallander.cache (8923) - DEBUG - CacheInvalidationThread started
2016-04-14 13:01:55,199 - wallander.cache (8923) - DEBUG - Checking cache items...
2016-04-14 13:01:55,199 - wallander.cache (8923) - DEBUG - Checking cache items...
2016-04-14 13:02:00,817 - wallander.application (8923) - DEBUG - REQUEST_URI: /stagyy/
2016-04-14 13:02:00,817 - wallander.application (8923) - DEBUG - REQUEST_URI: /stagyy/
2016-04-14 13:02:00,819 - wallander.application (8923) - DEBUG - Data provider name: 'stagyy'
2016-04-14 13:02:00,819 - wallander.application (8923) - DEBUG - Data provider name: 'stagyy'
2016-04-14 13:02:00,820 - wallander.application (8923) - DEBUG - Data provider: <stagyy.DataProvider object at 0x7fe7fbdc57d0>
2016-04-14 13:02:00,820 - wallander.application (8923) - DEBUG - Data provider: <stagyy.DataProvider object at 0x7fe7fbdc57d0>
2016-04-14 13:02:00,821 - wallander.data_providers (8923) - DEBUG - Checking path: []
2016-04-14 13:02:00,821 - wallander.data_providers (8923) - DEBUG - Checking path: []
2016-04-14 13:02:00,821 - stagyy (8923) - DEBUG - Checking path: /var/wallander/data/stagyy
2016-04-14 13:02:43,416 - config (8941) - WARNING - Couldn't find logger 'LOG' in '<module '__main__' (built-in)>'
2016-04-14 13:02:45,101 - wallander.application (8941) - DEBUG - REQUEST_URI: /stagyy/
2016-04-14 13:02:45,101 - wallander.application (8941) - DEBUG - REQUEST_URI: /stagyy/
2016-04-14 13:02:45,101 - wallander.application (8941) - DEBUG - Data provider name: 'stagyy'
2016-04-14 13:02:45,101 - wallander.application (8941) - DEBUG - Data provider name: 'stagyy'
2016-04-14 13:02:45,102 - wallander.application (8941) - DEBUG - Data provider: <stagyy.DataProvider object at 0x7f9565606490>
2016-04-14 13:02:45,102 - wallander.application (8941) - DEBUG - Data provider: <stagyy.DataProvider object at 0x7f9565606490>
2016-04-14 13:02:45,102 - wallander.data_providers (8941) - DEBUG - Checking path: []
2016-04-14 13:02:45,102 - wallander.data_providers (8941) - DEBUG - Checking path: []
2016-04-14 13:02:45,103 - stagyy (8941) - DEBUG - Checking path: /var/wallander/data/stagyy
2016-04-14 13:07:43,494 - wallander.cache (8941) - DEBUG - Checking cache items...
2016-04-14 13:07:43,494 - wallander.cache (8941) - DEBUG - Checking cache items...
2016-04-14 13:08:45,956 - config (9066) - WARNING - Couldn't find logger 'LOG' in '<module '__main__' (built-in)>'
2016-04-14 13:08:45,960 - wallander.cache (9066) - DEBUG - CacheInvalidationThread started
2016-04-14 13:08:45,960 - wallander.cache (9066) - DEBUG - CacheInvalidationThread started
2016-04-14 13:08:45,960 - wallander.cache (9066) - DEBUG - Checking cache items...
2016-04-14 13:08:45,960 - wallander.cache (9066) - DEBUG - Checking cache items...
2016-04-14 13:08:51,136 - wallander.application (9066) - DEBUG - REQUEST_URI: /stagyy/
2016-04-14 13:08:51,136 - wallander.application (9066) - DEBUG - REQUEST_URI: /stagyy/
2016-04-14 13:08:51,137 - wallander.application (9066) - DEBUG - Data provider name: 'stagyy'
2016-04-14 13:08:51,137 - wallander.application (9066) - DEBUG - Data provider name: 'stagyy'
2016-04-14 13:08:51,137 - wallander.application (9066) - DEBUG - Data provider: <stagyy.DataProvider object at 0x7fab8ac8f490>
2016-04-14 13:08:51,137 - wallander.application (9066) - DEBUG - Data provider: <stagyy.DataProvider object at 0x7fab8ac8f490>
2016-04-14 13:08:51,138 - wallander.data_providers (9066) - DEBUG - Checking path: []
2016-04-14 13:08:51,138 - wallander.data_providers (9066) - DEBUG - Checking path: []
2016-04-14 13:08:51,140 - stagyy (9066) - DEBUG - Checking path: /var/wallander/data/stagyy
2016-04-14 13:08:51,140 - wallander.application (9066) - ERROR - Exception processing request
Traceback (most recent call last):
  File "/var/wallander/python/wallander/application.py", line 49, in __call__
    return response.respond_ok(r,start_response)
  File "/var/wallander/python/wallander/response.py", line 64, in respond_ok
    return iter([json.dumps(v)])
  File "/usr/lib/python2.7/json/__init__.py", line 243, in dumps
    return _default_encoder.encode(obj)
  File "/usr/lib/python2.7/json/encoder.py", line 207, in encode
    chunks = self.iterencode(o, _one_shot=True)
  File "/usr/lib/python2.7/json/encoder.py", line 270, in iterencode
    return _iterencode(o, 0)
  File "/var/wallander/python/wallander/make_json_serialize_objects.py", line 10, in _default
    return obj.to_json()
  File "/var/wallander/data_providers/stagyy/__init__.py", line 62, in to_json
    "name": os.path.basename(self.directory),
AttributeError: 'H5Folder' object has no attribute 'directory'
2016-04-14 13:08:51,140 - wallander.application (9066) - ERROR - Exception processing request
Traceback (most recent call last):
  File "/var/wallander/python/wallander/application.py", line 49, in __call__
    return response.respond_ok(r,start_response)
  File "/var/wallander/python/wallander/response.py", line 64, in respond_ok
    return iter([json.dumps(v)])
  File "/usr/lib/python2.7/json/__init__.py", line 243, in dumps
    return _default_encoder.encode(obj)
  File "/usr/lib/python2.7/json/encoder.py", line 207, in encode
    chunks = self.iterencode(o, _one_shot=True)
  File "/usr/lib/python2.7/json/encoder.py", line 270, in iterencode
    return _iterencode(o, 0)
  File "/var/wallander/python/wallander/make_json_serialize_objects.py", line 10, in _default
    return obj.to_json()
  File "/var/wallander/data_providers/stagyy/__init__.py", line 62, in to_json
    "name": os.path.basename(self.directory),
AttributeError: 'H5Folder' object has no attribute 'directory'
2016-04-14 13:09:28,877 - wallander.application (9066) - DEBUG - REQUEST_URI: /stagyy/
2016-04-14 13:09:28,877 - wallander.application (9066) - DEBUG - REQUEST_URI: /stagyy/
2016-04-14 13:09:28,878 - wallander.application (9066) - DEBUG - Data provider name: 'stagyy'
2016-04-14 13:09:28,878 - wallander.application (9066) - DEBUG - Data provider name: 'stagyy'
2016-04-14 13:09:28,878 - wallander.application (9066) - DEBUG - Data provider: <stagyy.DataProvider object at 0x7fab8ac8f490>
2016-04-14 13:09:28,878 - wallander.application (9066) - DEBUG - Data provider: <stagyy.DataProvider object at 0x7fab8ac8f490>
2016-04-14 13:09:28,878 - wallander.data_providers (9066) - DEBUG - Checking path: []
2016-04-14 13:09:28,878 - wallander.data_providers (9066) - DEBUG - Checking path: []
2016-04-14 13:09:28,879 - stagyy (9066) - DEBUG - Checking path: /var/wallander/data/stagyy
2016-04-14 13:09:28,879 - wallander.application (9066) - ERROR - Exception processing request
Traceback (most recent call last):
  File "/var/wallander/python/wallander/application.py", line 49, in __call__
    return response.respond_ok(r,start_response)
  File "/var/wallander/python/wallander/response.py", line 64, in respond_ok
    return iter([json.dumps(v)])
  File "/usr/lib/python2.7/json/__init__.py", line 243, in dumps
    return _default_encoder.encode(obj)
  File "/usr/lib/python2.7/json/encoder.py", line 207, in encode
    chunks = self.iterencode(o, _one_shot=True)
  File "/usr/lib/python2.7/json/encoder.py", line 270, in iterencode
    return _iterencode(o, 0)
  File "/var/wallander/python/wallander/make_json_serialize_objects.py", line 10, in _default
    return obj.to_json()
  File "/var/wallander/data_providers/stagyy/__init__.py", line 62, in to_json
    "name": os.path.basename(self.directory),
AttributeError: 'H5Folder' object has no attribute 'directory'
2016-04-14 13:09:28,879 - wallander.application (9066) - ERROR - Exception processing request
Traceback (most recent call last):
  File "/var/wallander/python/wallander/application.py", line 49, in __call__
    return response.respond_ok(r,start_response)
  File "/var/wallander/python/wallander/response.py", line 64, in respond_ok
    return iter([json.dumps(v)])
  File "/usr/lib/python2.7/json/__init__.py", line 243, in dumps
    return _default_encoder.encode(obj)
  File "/usr/lib/python2.7/json/encoder.py", line 207, in encode
    chunks = self.iterencode(o, _one_shot=True)
  File "/usr/lib/python2.7/json/encoder.py", line 270, in iterencode
    return _iterencode(o, 0)
  File "/var/wallander/python/wallander/make_json_serialize_objects.py", line 10, in _default
    return obj.to_json()
  File "/var/wallander/data_providers/stagyy/__init__.py", line 62, in to_json
    "name": os.path.basename(self.directory),
AttributeError: 'H5Folder' object has no attribute 'directory'
2016-04-14 13:09:33,234 - config (9104) - WARNING - Couldn't find logger 'LOG' in '<module '__main__' (built-in)>'
2016-04-14 13:09:33,238 - wallander.cache (9104) - DEBUG - CacheInvalidationThread started
2016-04-14 13:09:33,238 - wallander.cache (9104) - DEBUG - CacheInvalidationThread started
2016-04-14 13:09:33,238 - wallander.cache (9104) - DEBUG - Checking cache items...
2016-04-14 13:09:33,238 - wallander.cache (9104) - DEBUG - Checking cache items...
2016-04-14 13:09:35,134 - wallander.application (9104) - DEBUG - REQUEST_URI: /stagyy/
2016-04-14 13:09:35,134 - wallander.application (9104) - DEBUG - REQUEST_URI: /stagyy/
2016-04-14 13:09:35,138 - wallander.application (9104) - DEBUG - Data provider name: 'stagyy'
2016-04-14 13:09:35,138 - wallander.application (9104) - DEBUG - Data provider name: 'stagyy'
2016-04-14 13:09:35,138 - wallander.application (9104) - DEBUG - Data provider: <stagyy.DataProvider object at 0x7f61a54bf410>
2016-04-14 13:09:35,138 - wallander.application (9104) - DEBUG - Data provider: <stagyy.DataProvider object at 0x7f61a54bf410>
2016-04-14 13:09:35,138 - wallander.data_providers (9104) - DEBUG - Checking path: []
2016-04-14 13:09:35,138 - wallander.data_providers (9104) - DEBUG - Checking path: []
2016-04-14 13:09:35,138 - stagyy (9104) - DEBUG - Checking path: /var/wallander/data/stagyy
2016-04-14 13:09:35,139 - wallander.application (9104) - ERROR - Exception processing request
Traceback (most recent call last):
  File "/var/wallander/python/wallander/application.py", line 49, in __call__
    return response.respond_ok(r,start_response)
  File "/var/wallander/python/wallander/response.py", line 64, in respond_ok
    return iter([json.dumps(v)])
  File "/usr/lib/python2.7/json/__init__.py", line 243, in dumps
    return _default_encoder.encode(obj)
  File "/usr/lib/python2.7/json/encoder.py", line 207, in encode
    chunks = self.iterencode(o, _one_shot=True)
  File "/usr/lib/python2.7/json/encoder.py", line 270, in iterencode
    return _iterencode(o, 0)
  File "/var/wallander/python/wallander/make_json_serialize_objects.py", line 10, in _default
    return obj.to_json()
  File "/var/wallander/data_providers/stagyy/__init__.py", line 63, in to_json
    "icon": os.path.join(self.data_provider.__module__,wallander.ICONS,'folder.svg'),
AttributeError: 'H5Folder' object has no attribute 'data_provider'
2016-04-14 13:09:35,139 - wallander.application (9104) - ERROR - Exception processing request
Traceback (most recent call last):
  File "/var/wallander/python/wallander/application.py", line 49, in __call__
    return response.respond_ok(r,start_response)
  File "/var/wallander/python/wallander/response.py", line 64, in respond_ok
    return iter([json.dumps(v)])
  File "/usr/lib/python2.7/json/__init__.py", line 243, in dumps
    return _default_encoder.encode(obj)
  File "/usr/lib/python2.7/json/encoder.py", line 207, in encode
    chunks = self.iterencode(o, _one_shot=True)
  File "/usr/lib/python2.7/json/encoder.py", line 270, in iterencode
    return _iterencode(o, 0)
  File "/var/wallander/python/wallander/make_json_serialize_objects.py", line 10, in _default
    return obj.to_json()
  File "/var/wallander/data_providers/stagyy/__init__.py", line 63, in to_json
    "icon": os.path.join(self.data_provider.__module__,wallander.ICONS,'folder.svg'),
AttributeError: 'H5Folder' object has no attribute 'data_provider'
2016-04-14 13:11:32,616 - config (9172) - WARNING - Couldn't find logger 'LOG' in '<module '__main__' (built-in)>'
2016-04-14 13:11:32,620 - wallander.cache (9172) - DEBUG - CacheInvalidationThread started
2016-04-14 13:11:32,620 - wallander.cache (9172) - DEBUG - CacheInvalidationThread started
2016-04-14 13:11:32,620 - wallander.cache (9172) - DEBUG - Checking cache items...
2016-04-14 13:11:32,620 - wallander.cache (9172) - DEBUG - Checking cache items...
2016-04-14 13:11:35,379 - wallander.application (9172) - DEBUG - REQUEST_URI: /stagyy/
2016-04-14 13:11:35,379 - wallander.application (9172) - DEBUG - REQUEST_URI: /stagyy/
2016-04-14 13:11:35,381 - wallander.application (9172) - DEBUG - Data provider name: 'stagyy'
2016-04-14 13:11:35,381 - wallander.application (9172) - DEBUG - Data provider name: 'stagyy'
2016-04-14 13:11:35,382 - wallander.application (9172) - DEBUG - Data provider: <stagyy.DataProvider object at 0x7f56e23f0410>
2016-04-14 13:11:35,382 - wallander.application (9172) - DEBUG - Data provider: <stagyy.DataProvider object at 0x7f56e23f0410>
2016-04-14 13:11:35,382 - wallander.data_providers (9172) - DEBUG - Checking path: []
2016-04-14 13:11:35,382 - wallander.data_providers (9172) - DEBUG - Checking path: []
2016-04-14 13:11:35,382 - stagyy (9172) - DEBUG - Checking path: /var/wallander/data/stagyy
2016-04-14 13:11:54,449 - wallander.application (9172) - DEBUG - REQUEST_URI: /stagyy/_icons/folder.svg
2016-04-14 13:11:54,449 - wallander.application (9172) - DEBUG - REQUEST_URI: /stagyy/_icons/folder.svg
2016-04-14 13:11:54,450 - wallander.application (9172) - DEBUG - Data provider name: 'stagyy'
2016-04-14 13:11:54,450 - wallander.application (9172) - DEBUG - Data provider name: 'stagyy'
2016-04-14 13:11:54,451 - wallander.application (9172) - DEBUG - Data provider: <stagyy.DataProvider object at 0x7f56e23f0410>
2016-04-14 13:11:54,451 - wallander.application (9172) - DEBUG - Data provider: <stagyy.DataProvider object at 0x7f56e23f0410>
2016-04-14 13:11:54,451 - wallander.data_providers (9172) - DEBUG - Checking path: ['_icons', 'folder.svg']
2016-04-14 13:11:54,451 - wallander.data_providers (9172) - DEBUG - Checking path: ['_icons', 'folder.svg']
2016-04-14 13:11:54,451 - stagyy (9172) - DEBUG - Checking path: /var/wallander/data/stagyy/_icons/folder.svg
2016-04-14 13:11:54,451 - stagyy (9172) - DEBUG - Checking path: /var/wallander/data/stagyy/_icons
2016-04-14 13:13:11,216 - wallander.application (9172) - DEBUG - REQUEST_URI: /stagyy/
2016-04-14 13:13:11,216 - wallander.application (9172) - DEBUG - REQUEST_URI: /stagyy/
2016-04-14 13:13:11,218 - wallander.application (9172) - DEBUG - Data provider name: 'stagyy'
2016-04-14 13:13:11,218 - wallander.application (9172) - DEBUG - Data provider name: 'stagyy'
2016-04-14 13:13:11,219 - wallander.application (9172) - DEBUG - Data provider: <stagyy.DataProvider object at 0x7f56e23f0410>
2016-04-14 13:13:11,219 - wallander.application (9172) - DEBUG - Data provider: <stagyy.DataProvider object at 0x7f56e23f0410>
2016-04-14 13:13:11,219 - wallander.data_providers (9172) - DEBUG - Checking path: []
2016-04-14 13:13:11,219 - wallander.data_providers (9172) - DEBUG - Checking path: []
2016-04-14 13:13:11,220 - stagyy (9172) - DEBUG - Checking path: /var/wallander/data/stagyy
2016-04-14 13:13:33,637 - wallander.application (9172) - DEBUG - REQUEST_URI: /
2016-04-14 13:13:33,637 - wallander.application (9172) - DEBUG - REQUEST_URI: /
2016-04-14 13:13:33,639 - wallander.application (9172) - DEBUG - Data provider name: ''
2016-04-14 13:13:33,639 - wallander.application (9172) - DEBUG - Data provider name: ''
2016-04-14 13:13:33,639 - wallander.application (9172) - DEBUG - Data provider: <function dp_provider_response at 0x7f56e23eec08>
2016-04-14 13:13:33,639 - wallander.application (9172) - DEBUG - Data provider: <function dp_provider_response at 0x7f56e23eec08>
2016-04-14 13:13:33,640 - wallander.application (9172) - ERROR - Exception processing request
Traceback (most recent call last):
  File "/var/wallander/python/wallander/application.py", line 49, in __call__
    return response.respond_ok(r,start_response)
  File "/var/wallander/python/wallander/response.py", line 64, in respond_ok
    return iter([json.dumps(v)])
  File "/usr/lib/python2.7/json/__init__.py", line 243, in dumps
    return _default_encoder.encode(obj)
  File "/usr/lib/python2.7/json/encoder.py", line 207, in encode
    chunks = self.iterencode(o, _one_shot=True)
  File "/usr/lib/python2.7/json/encoder.py", line 270, in iterencode
    return _iterencode(o, 0)
  File "/var/wallander/python/wallander/make_json_serialize_objects.py", line 12, in _default
    return _default.default(obj)
  File "/usr/lib/python2.7/json/encoder.py", line 184, in default
    raise TypeError(repr(o) + " is not JSON serializable")
TypeError: <listiterator object at 0x7f56eea09c90> is not JSON serializable
2016-04-14 13:13:33,640 - wallander.application (9172) - ERROR - Exception processing request
Traceback (most recent call last):
  File "/var/wallander/python/wallander/application.py", line 49, in __call__
    return response.respond_ok(r,start_response)
  File "/var/wallander/python/wallander/response.py", line 64, in respond_ok
    return iter([json.dumps(v)])
  File "/usr/lib/python2.7/json/__init__.py", line 243, in dumps
    return _default_encoder.encode(obj)
  File "/usr/lib/python2.7/json/encoder.py", line 207, in encode
    chunks = self.iterencode(o, _one_shot=True)
  File "/usr/lib/python2.7/json/encoder.py", line 270, in iterencode
    return _iterencode(o, 0)
  File "/var/wallander/python/wallander/make_json_serialize_objects.py", line 12, in _default
    return _default.default(obj)
  File "/usr/lib/python2.7/json/encoder.py", line 184, in default
    raise TypeError(repr(o) + " is not JSON serializable")
TypeError: <listiterator object at 0x7f56eea09c90> is not JSON serializable
2016-04-14 13:15:13,018 - config (9227) - WARNING - Couldn't find logger 'LOG' in '<module '__main__' (built-in)>'
2016-04-14 13:15:13,022 - wallander.cache (9227) - DEBUG - CacheInvalidationThread started
2016-04-14 13:15:13,022 - wallander.cache (9227) - DEBUG - CacheInvalidationThread started
2016-04-14 13:15:13,022 - wallander.cache (9227) - DEBUG - Checking cache items...
2016-04-14 13:15:13,022 - wallander.cache (9227) - DEBUG - Checking cache items...
2016-04-14 13:15:15,805 - wallander.application (9227) - DEBUG - REQUEST_URI: /
2016-04-14 13:15:15,805 - wallander.application (9227) - DEBUG - REQUEST_URI: /
2016-04-14 13:15:15,806 - wallander.application (9227) - DEBUG - Data provider name: ''
2016-04-14 13:15:15,806 - wallander.application (9227) - DEBUG - Data provider name: ''
2016-04-14 13:15:15,806 - wallander.application (9227) - DEBUG - Data provider: <function dp_provider_response at 0x7fd6abc7fc08>
2016-04-14 13:15:15,806 - wallander.application (9227) - DEBUG - Data provider: <function dp_provider_response at 0x7fd6abc7fc08>
2016-04-14 13:15:51,850 - wallander.application (9227) - DEBUG - REQUEST_URI: /stagyy
2016-04-14 13:15:51,850 - wallander.application (9227) - DEBUG - REQUEST_URI: /stagyy
2016-04-14 13:15:51,852 - wallander.application (9227) - DEBUG - Data provider name: 'stagyy'
2016-04-14 13:15:51,852 - wallander.application (9227) - DEBUG - Data provider name: 'stagyy'
2016-04-14 13:15:51,852 - wallander.application (9227) - DEBUG - Data provider: <stagyy.DataProvider object at 0x7fd6abc814d0>
2016-04-14 13:15:51,852 - wallander.application (9227) - DEBUG - Data provider: <stagyy.DataProvider object at 0x7fd6abc814d0>
2016-04-14 13:15:51,853 - wallander.data_providers (9227) - DEBUG - Checking path: []
2016-04-14 13:15:51,853 - wallander.data_providers (9227) - DEBUG - Checking path: []
2016-04-14 13:15:51,854 - stagyy (9227) - DEBUG - Checking path: /var/wallander/data/stagyy
2016-04-14 13:20:13,133 - wallander.cache (9227) - DEBUG - Checking cache items...
2016-04-14 13:20:13,133 - wallander.cache (9227) - DEBUG - Checking cache items...
2016-04-14 13:22:53,901 - config (9367) - WARNING - Couldn't find logger 'LOG' in '<module '__main__' (built-in)>'
2016-04-14 13:22:53,905 - wallander.cache (9367) - DEBUG - CacheInvalidationThread started
2016-04-14 13:22:53,905 - wallander.cache (9367) - DEBUG - CacheInvalidationThread started
2016-04-14 13:22:53,905 - wallander.cache (9367) - DEBUG - Checking cache items...
2016-04-14 13:22:53,905 - wallander.cache (9367) - DEBUG - Checking cache items...
2016-04-14 13:22:57,279 - wallander.application (9367) - DEBUG - REQUEST_URI: /stagyy
2016-04-14 13:22:57,279 - wallander.application (9367) - DEBUG - REQUEST_URI: /stagyy
2016-04-14 13:22:57,280 - wallander.application (9367) - DEBUG - Data provider name: 'stagyy'
2016-04-14 13:22:57,280 - wallander.application (9367) - DEBUG - Data provider name: 'stagyy'
2016-04-14 13:22:57,281 - wallander.application (9367) - DEBUG - Data provider: <stagyy.DataProvider object at 0x7ff9700bc450>
2016-04-14 13:22:57,281 - wallander.application (9367) - DEBUG - Data provider: <stagyy.DataProvider object at 0x7ff9700bc450>
2016-04-14 13:22:57,281 - wallander.data_providers (9367) - DEBUG - Checking path: []
2016-04-14 13:22:57,281 - wallander.data_providers (9367) - DEBUG - Checking path: []
2016-04-14 13:22:57,282 - stagyy (9367) - DEBUG - Checking path: /var/wallander/data/stagyy
2016-04-14 13:23:29,784 - config (9387) - WARNING - Couldn't find logger 'LOG' in '<module '__main__' (built-in)>'
2016-04-14 13:23:29,787 - wallander.cache (9387) - DEBUG - CacheInvalidationThread started
2016-04-14 13:23:29,787 - wallander.cache (9387) - DEBUG - CacheInvalidationThread started
2016-04-14 13:23:29,788 - wallander.cache (9387) - DEBUG - Checking cache items...
2016-04-14 13:23:29,788 - wallander.cache (9387) - DEBUG - Checking cache items...
2016-04-14 13:23:31,249 - wallander.application (9387) - DEBUG - REQUEST_URI: /stagyy
2016-04-14 13:23:31,249 - wallander.application (9387) - DEBUG - REQUEST_URI: /stagyy
2016-04-14 13:23:31,251 - wallander.application (9387) - DEBUG - Data provider name: 'stagyy'
2016-04-14 13:23:31,251 - wallander.application (9387) - DEBUG - Data provider name: 'stagyy'
2016-04-14 13:23:31,252 - wallander.application (9387) - DEBUG - Data provider: <stagyy.DataProvider object at 0x7f1af21f2450>
2016-04-14 13:23:31,252 - wallander.application (9387) - DEBUG - Data provider: <stagyy.DataProvider object at 0x7f1af21f2450>
2016-04-14 13:23:31,252 - wallander.data_providers (9387) - DEBUG - Checking path: []
2016-04-14 13:23:31,252 - wallander.data_providers (9387) - DEBUG - Checking path: []
2016-04-14 13:23:31,253 - stagyy (9387) - DEBUG - Checking path: /var/wallander/data/stagyy
2016-04-14 13:23:31,253 - stagyy (9387) - DEBUG - Root
2016-04-14 13:23:58,363 - config (9400) - WARNING - Couldn't find logger 'LOG' in '<module '__main__' (built-in)>'
2016-04-14 13:23:58,366 - wallander.cache (9400) - DEBUG - CacheInvalidationThread started
2016-04-14 13:23:58,366 - wallander.cache (9400) - DEBUG - CacheInvalidationThread started
2016-04-14 13:23:58,367 - wallander.cache (9400) - DEBUG - Checking cache items...
2016-04-14 13:23:58,367 - wallander.cache (9400) - DEBUG - Checking cache items...
2016-04-14 13:23:59,447 - wallander.application (9400) - DEBUG - REQUEST_URI: /stagyy
2016-04-14 13:23:59,447 - wallander.application (9400) - DEBUG - REQUEST_URI: /stagyy
2016-04-14 13:23:59,449 - wallander.application (9400) - DEBUG - Data provider name: 'stagyy'
2016-04-14 13:23:59,449 - wallander.application (9400) - DEBUG - Data provider name: 'stagyy'
2016-04-14 13:23:59,450 - wallander.application (9400) - DEBUG - Data provider: <stagyy.DataProvider object at 0x7f90b3c43450>
2016-04-14 13:23:59,450 - wallander.application (9400) - DEBUG - Data provider: <stagyy.DataProvider object at 0x7f90b3c43450>
2016-04-14 13:23:59,451 - wallander.data_providers (9400) - DEBUG - Checking path: []
2016-04-14 13:23:59,451 - wallander.data_providers (9400) - DEBUG - Checking path: []
2016-04-14 13:23:59,452 - stagyy (9400) - DEBUG - Checking path: /var/wallander/data/stagyy
2016-04-14 13:23:59,452 - stagyy (9400) - DEBUG - Root
2016-04-14 13:23:59,453 - wallander.application (9400) - ERROR - Exception processing request
Traceback (most recent call last):
  File "/var/wallander/python/wallander/application.py", line 45, in __call__
    r=dp(environ,start_response,path)
  File "/var/wallander/python/wallander/data_providers.py", line 47, in __call__
    result=self.call(environ,start_response,path)
  File "/var/wallander/data_providers/stagyy/__init__.py", line 50, in call
    response['icon']=self.icon
TypeError: 'H5Folder' object does not support item assignment
2016-04-14 13:23:59,453 - wallander.application (9400) - ERROR - Exception processing request
Traceback (most recent call last):
  File "/var/wallander/python/wallander/application.py", line 45, in __call__
    r=dp(environ,start_response,path)
  File "/var/wallander/python/wallander/data_providers.py", line 47, in __call__
    result=self.call(environ,start_response,path)
  File "/var/wallander/data_providers/stagyy/__init__.py", line 50, in call
    response['icon']=self.icon
TypeError: 'H5Folder' object does not support item assignment
2016-04-14 13:26:29,081 - config (9440) - WARNING - Couldn't find logger 'LOG' in '<module '__main__' (built-in)>'
2016-04-14 13:26:29,085 - wallander.cache (9440) - DEBUG - CacheInvalidationThread started
2016-04-14 13:26:29,085 - wallander.cache (9440) - DEBUG - CacheInvalidationThread started
2016-04-14 13:26:29,085 - wallander.cache (9440) - DEBUG - Checking cache items...
2016-04-14 13:26:29,085 - wallander.cache (9440) - DEBUG - Checking cache items...
2016-04-14 13:26:31,840 - wallander.application (9440) - DEBUG - REQUEST_URI: /stagyy
2016-04-14 13:26:31,840 - wallander.application (9440) - DEBUG - REQUEST_URI: /stagyy
2016-04-14 13:26:31,842 - wallander.application (9440) - DEBUG - Data provider name: 'stagyy'
2016-04-14 13:26:31,842 - wallander.application (9440) - DEBUG - Data provider name: 'stagyy'
2016-04-14 13:26:31,843 - wallander.application (9440) - DEBUG - Data provider: <stagyy.DataProvider object at 0x7f7f240d13d0>
2016-04-14 13:26:31,843 - wallander.application (9440) - DEBUG - Data provider: <stagyy.DataProvider object at 0x7f7f240d13d0>
2016-04-14 13:26:31,843 - wallander.data_providers (9440) - DEBUG - Checking path: []
2016-04-14 13:26:31,843 - wallander.data_providers (9440) - DEBUG - Checking path: []
2016-04-14 13:26:31,844 - stagyy (9440) - DEBUG - Checking path: /var/wallander/data/stagyy
2016-04-14 13:26:31,844 - stagyy (9440) - DEBUG - Root
2016-04-14 13:26:49,490 - wallander.application (9440) - DEBUG - REQUEST_URI: /stagyy/_icons/stagyy.svg
2016-04-14 13:26:49,490 - wallander.application (9440) - DEBUG - REQUEST_URI: /stagyy/_icons/stagyy.svg
2016-04-14 13:26:49,491 - wallander.application (9440) - DEBUG - Data provider name: 'stagyy'
2016-04-14 13:26:49,491 - wallander.application (9440) - DEBUG - Data provider name: 'stagyy'
2016-04-14 13:26:49,492 - wallander.application (9440) - DEBUG - Data provider: <stagyy.DataProvider object at 0x7f7f240d13d0>
2016-04-14 13:26:49,492 - wallander.application (9440) - DEBUG - Data provider: <stagyy.DataProvider object at 0x7f7f240d13d0>
2016-04-14 13:26:49,492 - wallander.data_providers (9440) - DEBUG - Checking path: ['_icons', 'stagyy.svg']
2016-04-14 13:26:49,492 - wallander.data_providers (9440) - DEBUG - Checking path: ['_icons', 'stagyy.svg']
2016-04-14 13:26:49,493 - stagyy (9440) - DEBUG - Checking path: /var/wallander/data/stagyy/_icons/stagyy.svg
2016-04-14 13:26:49,493 - stagyy (9440) - DEBUG - Checking path: /var/wallander/data/stagyy/_icons
2016-04-14 13:30:06,469 - wallander.application (9440) - DEBUG - REQUEST_URI: /stagyy/_icons/stagyy.svg
2016-04-14 13:30:06,469 - wallander.application (9440) - DEBUG - REQUEST_URI: /stagyy/_icons/stagyy.svg
2016-04-14 13:30:06,470 - wallander.application (9440) - DEBUG - Data provider name: 'stagyy'
2016-04-14 13:30:06,470 - wallander.application (9440) - DEBUG - Data provider name: 'stagyy'
2016-04-14 13:30:06,470 - wallander.application (9440) - DEBUG - Data provider: <stagyy.DataProvider object at 0x7f7f240d13d0>
2016-04-14 13:30:06,470 - wallander.application (9440) - DEBUG - Data provider: <stagyy.DataProvider object at 0x7f7f240d13d0>
2016-04-14 13:30:06,471 - wallander.data_providers (9440) - DEBUG - Checking path: ['_icons', 'stagyy.svg']
2016-04-14 13:30:06,471 - wallander.data_providers (9440) - DEBUG - Checking path: ['_icons', 'stagyy.svg']
2016-04-14 13:30:06,471 - stagyy (9440) - DEBUG - Checking path: /var/wallander/data/stagyy/_icons/stagyy.svg
2016-04-14 13:30:06,471 - stagyy (9440) - DEBUG - Checking path: /var/wallander/data/stagyy/_icons
2016-04-14 13:30:06,471 - stagyy (9440) - DEBUG - Checking path: /var/wallander/data/stagyy
2016-04-14 13:30:06,472 - stagyy (9440) - DEBUG - Root
2016-04-14 13:31:24,370 - config (9560) - WARNING - Couldn't find logger 'LOG' in '<module '__main__' (built-in)>'
2016-04-14 13:31:24,374 - wallander.cache (9560) - DEBUG - CacheInvalidationThread started
2016-04-14 13:31:24,374 - wallander.cache (9560) - DEBUG - CacheInvalidationThread started
2016-04-14 13:31:24,375 - wallander.cache (9560) - DEBUG - Checking cache items...
2016-04-14 13:31:24,375 - wallander.cache (9560) - DEBUG - Checking cache items...
2016-04-14 13:31:25,276 - wallander.application (9560) - DEBUG - REQUEST_URI: /stagyy/_icons/stagyy.svg
2016-04-14 13:31:25,276 - wallander.application (9560) - DEBUG - REQUEST_URI: /stagyy/_icons/stagyy.svg
2016-04-14 13:31:25,277 - wallander.application (9560) - DEBUG - Data provider name: 'stagyy'
2016-04-14 13:31:25,277 - wallander.application (9560) - DEBUG - Data provider name: 'stagyy'
2016-04-14 13:31:25,278 - wallander.application (9560) - DEBUG - Data provider: <stagyy.DataProvider object at 0x7ff868a203d0>
2016-04-14 13:31:25,278 - wallander.application (9560) - DEBUG - Data provider: <stagyy.DataProvider object at 0x7ff868a203d0>
2016-04-14 13:31:25,279 - wallander.data_providers (9560) - DEBUG - Checking path: ['_icons', 'stagyy.svg']
2016-04-14 13:31:25,279 - wallander.data_providers (9560) - DEBUG - Checking path: ['_icons', 'stagyy.svg']
2016-04-14 13:31:25,280 - stagyy (9560) - DEBUG - Checking path: /var/wallander/data/stagyy/_icons/stagyy.svg
2016-04-14 13:31:25,280 - stagyy (9560) - DEBUG - Checking path: /var/wallander/data/stagyy/_icons
2016-04-14 13:31:25,280 - stagyy (9560) - DEBUG - Checking path: /var/wallander/data/stagyy
2016-04-14 13:31:25,281 - wallander.application (9560) - ERROR - Exception processing request
Traceback (most recent call last):
  File "/var/wallander/python/wallander/application.py", line 45, in __call__
    r=dp(environ,start_response,path)
  File "/var/wallander/python/wallander/data_providers.py", line 50, in __call__
    if path[0][0]=='_':
IndexError: list index out of range
2016-04-14 13:31:25,281 - wallander.application (9560) - ERROR - Exception processing request
Traceback (most recent call last):
  File "/var/wallander/python/wallander/application.py", line 45, in __call__
    r=dp(environ,start_response,path)
  File "/var/wallander/python/wallander/data_providers.py", line 50, in __call__
    if path[0][0]=='_':
IndexError: list index out of range
2016-04-14 13:36:24,473 - wallander.cache (9560) - DEBUG - Checking cache items...
2016-04-14 13:36:24,473 - wallander.cache (9560) - DEBUG - Checking cache items...
2016-04-14 13:39:25,649 - config (9728) - WARNING - Couldn't find logger 'LOG' in '<module '__main__' (built-in)>'
2016-04-14 13:39:25,653 - wallander.cache (9728) - DEBUG - CacheInvalidationThread started
2016-04-14 13:39:25,653 - wallander.cache (9728) - DEBUG - CacheInvalidationThread started
2016-04-14 13:39:25,653 - wallander.cache (9728) - DEBUG - Checking cache items...
2016-04-14 13:39:25,653 - wallander.cache (9728) - DEBUG - Checking cache items...
2016-04-14 13:41:05,385 - config (9778) - WARNING - Couldn't find logger 'LOG' in '<module '__main__' (built-in)>'
2016-04-14 13:41:05,389 - wallander.cache (9778) - DEBUG - CacheInvalidationThread started
2016-04-14 13:41:05,389 - wallander.cache (9778) - DEBUG - CacheInvalidationThread started
2016-04-14 13:41:05,390 - wallander.cache (9778) - DEBUG - Checking cache items...
2016-04-14 13:41:05,390 - wallander.cache (9778) - DEBUG - Checking cache items...
2016-04-14 13:46:05,490 - wallander.cache (9778) - DEBUG - Checking cache items...
2016-04-14 13:46:05,490 - wallander.cache (9778) - DEBUG - Checking cache items...
2016-04-14 13:49:30,335 - wallander.application (9778) - DEBUG - REQUEST_URI: stagyy/_icons/viscosity.svg
2016-04-14 13:49:30,335 - wallander.application (9778) - DEBUG - REQUEST_URI: stagyy/_icons/viscosity.svg
2016-04-14 13:49:30,337 - wallander.application (9778) - DEBUG - Data provider name: 'stagyy'
2016-04-14 13:49:30,337 - wallander.application (9778) - DEBUG - Data provider name: 'stagyy'
2016-04-14 13:49:30,338 - wallander.application (9778) - DEBUG - Data provider: <stagyy.DataProvider object at 0x7ff56b2e5450>
2016-04-14 13:49:30,338 - wallander.application (9778) - DEBUG - Data provider: <stagyy.DataProvider object at 0x7ff56b2e5450>
2016-04-14 13:49:30,339 - wallander.data_providers (9778) - DEBUG - Checking path: ['_icons', 'viscosity.svg']
2016-04-14 13:49:30,339 - wallander.data_providers (9778) - DEBUG - Checking path: ['_icons', 'viscosity.svg']
2016-04-14 13:49:30,340 - wallander.application (9778) - ERROR - Exception processing request
Traceback (most recent call last):
  File "/var/wallander/python/wallander/application.py", line 49, in __call__
    return response.respond_ok(r,start_response)
  File "/var/wallander/python/wallander/response.py", line 64, in respond_ok
    return iter([json.dumps(v)])
  File "/usr/lib/python2.7/json/__init__.py", line 243, in dumps
    return _default_encoder.encode(obj)
  File "/usr/lib/python2.7/json/encoder.py", line 207, in encode
    chunks = self.iterencode(o, _one_shot=True)
  File "/usr/lib/python2.7/json/encoder.py", line 270, in iterencode
    return _iterencode(o, 0)
  File "/var/wallander/python/wallander/make_json_serialize_objects.py", line 12, in _default
    return _default.default(obj)
  File "/usr/lib/python2.7/json/encoder.py", line 184, in default
    raise TypeError(repr(o) + " is not JSON serializable")
TypeError: <listiterator object at 0x7ff56a97dd50> is not JSON serializable
2016-04-14 13:49:30,340 - wallander.application (9778) - ERROR - Exception processing request
Traceback (most recent call last):
  File "/var/wallander/python/wallander/application.py", line 49, in __call__
    return response.respond_ok(r,start_response)
  File "/var/wallander/python/wallander/response.py", line 64, in respond_ok
    return iter([json.dumps(v)])
  File "/usr/lib/python2.7/json/__init__.py", line 243, in dumps
    return _default_encoder.encode(obj)
  File "/usr/lib/python2.7/json/encoder.py", line 207, in encode
    chunks = self.iterencode(o, _one_shot=True)
  File "/usr/lib/python2.7/json/encoder.py", line 270, in iterencode
    return _iterencode(o, 0)
  File "/var/wallander/python/wallander/make_json_serialize_objects.py", line 12, in _default
    return _default.default(obj)
  File "/usr/lib/python2.7/json/encoder.py", line 184, in default
    raise TypeError(repr(o) + " is not JSON serializable")
TypeError: <listiterator object at 0x7ff56a97dd50> is not JSON serializable
2016-04-14 13:51:05,585 - wallander.cache (9778) - DEBUG - Checking cache items...
2016-04-14 13:51:05,585 - wallander.cache (9778) - DEBUG - Checking cache items...
2016-04-14 13:56:05,642 - wallander.cache (9778) - DEBUG - Checking cache items...
2016-04-14 13:56:05,642 - wallander.cache (9778) - DEBUG - Checking cache items...
2016-04-14 13:56:42,979 - config (10216) - WARNING - Couldn't find logger 'LOG' in '<module '__main__' (built-in)>'
2016-04-14 13:56:47,138 - wallander.application (10216) - DEBUG - REQUEST_URI: stagyy/_icons/viscosity.svg
2016-04-14 13:56:47,138 - wallander.application (10216) - DEBUG - REQUEST_URI: stagyy/_icons/viscosity.svg
2016-04-14 13:56:47,140 - wallander.application (10216) - DEBUG - Data provider name: 'stagyy'
2016-04-14 13:56:47,140 - wallander.application (10216) - DEBUG - Data provider name: 'stagyy'
2016-04-14 13:56:47,141 - wallander.application (10216) - DEBUG - Data provider: <stagyy.DataProvider object at 0x7ff414888fd0>
2016-04-14 13:56:47,141 - wallander.application (10216) - DEBUG - Data provider: <stagyy.DataProvider object at 0x7ff414888fd0>
2016-04-14 13:56:47,142 - wallander.data_providers (10216) - DEBUG - Checking path: ['_icons', 'viscosity.svg']
2016-04-14 13:56:47,142 - wallander.data_providers (10216) - DEBUG - Checking path: ['_icons', 'viscosity.svg']
2016-04-14 13:56:47,143 - wallander.application (10216) - ERROR - Exception processing request
Traceback (most recent call last):
  File "/var/wallander/python/wallander/application.py", line 45, in __call__
    r=dp(environ,start_response,path)
  File "/var/wallander/python/wallander/data_providers.py", line 52, in __call__
    result=f(environ,start_response,path[1:])
  File "/var/wallander/python/wallander/data_providers.py", line 61, in _icons
    return resource_string(self.__module__+'._icons',path[1])
IndexError: list index out of range
2016-04-14 13:56:47,143 - wallander.application (10216) - ERROR - Exception processing request
Traceback (most recent call last):
  File "/var/wallander/python/wallander/application.py", line 45, in __call__
    r=dp(environ,start_response,path)
  File "/var/wallander/python/wallander/data_providers.py", line 52, in __call__
    result=f(environ,start_response,path[1:])
  File "/var/wallander/python/wallander/data_providers.py", line 61, in _icons
    return resource_string(self.__module__+'._icons',path[1])
IndexError: list index out of range
2016-04-14 14:01:15,795 - config (10360) - WARNING - Couldn't find logger 'LOG' in '<module '__main__' (built-in)>'
2016-04-14 14:01:15,796 - wallander.cache (10360) - DEBUG - CacheInvalidationThread started
2016-04-14 14:01:15,796 - wallander.cache (10360) - DEBUG - Checking cache items...
2016-04-14 14:01:17,303 - wallander.application (10360) - DEBUG - REQUEST_URI: stagyy/_icons/viscosity.svg
2016-04-14 14:01:17,303 - wallander.application (10360) - DEBUG - REQUEST_URI: stagyy/_icons/viscosity.svg
2016-04-14 14:01:17,304 - wallander.application (10360) - DEBUG - Data provider name: 'stagyy'
2016-04-14 14:01:17,304 - wallander.application (10360) - DEBUG - Data provider name: 'stagyy'
2016-04-14 14:01:17,304 - wallander.application (10360) - DEBUG - Data provider: <stagyy.DataProvider object at 0x7fbd69ec3fd0>
2016-04-14 14:01:17,304 - wallander.application (10360) - DEBUG - Data provider: <stagyy.DataProvider object at 0x7fbd69ec3fd0>
2016-04-14 14:01:17,305 - wallander.data_providers (10360) - DEBUG - Checking path: ['_icons', 'viscosity.svg']
2016-04-14 14:01:17,305 - wallander.data_providers (10360) - DEBUG - Checking path: ['_icons', 'viscosity.svg']
2016-04-14 14:01:32,046 - wallander.application (10360) - DEBUG - REQUEST_URI: stagyy/_icons/folder.svg
2016-04-14 14:01:32,046 - wallander.application (10360) - DEBUG - REQUEST_URI: stagyy/_icons/folder.svg
2016-04-14 14:01:32,047 - wallander.application (10360) - DEBUG - Data provider name: 'stagyy'
2016-04-14 14:01:32,047 - wallander.application (10360) - DEBUG - Data provider name: 'stagyy'
2016-04-14 14:01:32,047 - wallander.application (10360) - DEBUG - Data provider: <stagyy.DataProvider object at 0x7fbd69ec3fd0>
2016-04-14 14:01:32,047 - wallander.application (10360) - DEBUG - Data provider: <stagyy.DataProvider object at 0x7fbd69ec3fd0>
2016-04-14 14:01:32,048 - wallander.data_providers (10360) - DEBUG - Checking path: ['_icons', 'folder.svg']
2016-04-14 14:01:32,048 - wallander.data_providers (10360) - DEBUG - Checking path: ['_icons', 'folder.svg']
2016-04-14 14:01:32,051 - wallander.application (10360) - ERROR - Exception processing request
Traceback (most recent call last):
  File "/var/wallander/python/wallander/application.py", line 45, in __call__
    r=dp(environ,start_response,path)
  File "/var/wallander/python/wallander/data_providers.py", line 52, in __call__
    result=f(environ,start_response,path[1:])
  File "/var/wallander/python/wallander/data_providers.py", line 63, in _icons
    return resource_string('walander._icons',path[0])
  File "/usr/lib/python2.7/dist-packages/pkg_resources/__init__.py", line 1172, in resource_string
    return get_provider(package_or_requirement).get_resource_string(
  File "/usr/lib/python2.7/dist-packages/pkg_resources/__init__.py", line 435, in get_provider
    __import__(moduleOrReq)
ImportError: No module named walander._icons
2016-04-14 14:01:32,051 - wallander.application (10360) - ERROR - Exception processing request
Traceback (most recent call last):
  File "/var/wallander/python/wallander/application.py", line 45, in __call__
    r=dp(environ,start_response,path)
  File "/var/wallander/python/wallander/data_providers.py", line 52, in __call__
    result=f(environ,start_response,path[1:])
  File "/var/wallander/python/wallander/data_providers.py", line 63, in _icons
    return resource_string('walander._icons',path[0])
  File "/usr/lib/python2.7/dist-packages/pkg_resources/__init__.py", line 1172, in resource_string
    return get_provider(package_or_requirement).get_resource_string(
  File "/usr/lib/python2.7/dist-packages/pkg_resources/__init__.py", line 435, in get_provider
    __import__(moduleOrReq)
ImportError: No module named walander._icons
2016-04-14 14:02:19,594 - config (10381) - WARNING - Couldn't find logger 'LOG' in '<module '__main__' (built-in)>'
2016-04-14 14:02:19,888 - wallander.application (10381) - DEBUG - REQUEST_URI: stagyy/_icons/folder.svg
2016-04-14 14:02:19,888 - wallander.application (10381) - DEBUG - REQUEST_URI: stagyy/_icons/folder.svg
2016-04-14 14:02:19,888 - wallander.application (10381) - DEBUG - Data provider name: 'stagyy'
2016-04-14 14:02:19,888 - wallander.application (10381) - DEBUG - Data provider name: 'stagyy'
2016-04-14 14:02:19,891 - wallander.application (10381) - DEBUG - Data provider: <stagyy.DataProvider object at 0x7f6c1879afd0>
2016-04-14 14:02:19,891 - wallander.application (10381) - DEBUG - Data provider: <stagyy.DataProvider object at 0x7f6c1879afd0>
2016-04-14 14:02:19,891 - wallander.data_providers (10381) - DEBUG - Checking path: ['_icons', 'folder.svg']
2016-04-14 14:02:19,891 - wallander.data_providers (10381) - DEBUG - Checking path: ['_icons', 'folder.svg']
2016-04-14 14:02:38,811 - wallander.application (10381) - DEBUG - REQUEST_URI: stagyy/
2016-04-14 14:02:38,811 - wallander.application (10381) - DEBUG - REQUEST_URI: stagyy/
2016-04-14 14:02:38,813 - wallander.application (10381) - DEBUG - Data provider name: 'stagyy'
2016-04-14 14:02:38,813 - wallander.application (10381) - DEBUG - Data provider name: 'stagyy'
2016-04-14 14:02:38,814 - wallander.application (10381) - DEBUG - Data provider: <stagyy.DataProvider object at 0x7f6c1879afd0>
2016-04-14 14:02:38,814 - wallander.application (10381) - DEBUG - Data provider: <stagyy.DataProvider object at 0x7f6c1879afd0>
2016-04-14 14:02:38,814 - wallander.data_providers (10381) - DEBUG - Checking path: []
2016-04-14 14:02:38,814 - wallander.data_providers (10381) - DEBUG - Checking path: []
2016-04-14 14:02:38,815 - wallander.application (10381) - ERROR - Exception processing request
Traceback (most recent call last):
  File "/var/wallander/python/wallander/application.py", line 45, in __call__
    r=dp(environ,start_response,path)
  File "/var/wallander/python/wallander/data_providers.py", line 49, in __call__
    if path[0][0]=='_':
IndexError: list index out of range
2016-04-14 14:02:38,815 - wallander.application (10381) - ERROR - Exception processing request
Traceback (most recent call last):
  File "/var/wallander/python/wallander/application.py", line 45, in __call__
    r=dp(environ,start_response,path)
  File "/var/wallander/python/wallander/data_providers.py", line 49, in __call__
    if path[0][0]=='_':
IndexError: list index out of range
2016-04-14 14:02:49,011 - wallander.application (10381) - DEBUG - REQUEST_URI: stagyy
2016-04-14 14:02:49,011 - wallander.application (10381) - DEBUG - REQUEST_URI: stagyy
2016-04-14 14:02:49,012 - wallander.application (10381) - DEBUG - Data provider name: 'stagyy'
2016-04-14 14:02:49,012 - wallander.application (10381) - DEBUG - Data provider name: 'stagyy'
2016-04-14 14:02:49,013 - wallander.application (10381) - DEBUG - Data provider: <stagyy.DataProvider object at 0x7f6c1879afd0>
2016-04-14 14:02:49,013 - wallander.application (10381) - DEBUG - Data provider: <stagyy.DataProvider object at 0x7f6c1879afd0>
2016-04-14 14:02:49,013 - wallander.data_providers (10381) - DEBUG - Checking path: []
2016-04-14 14:02:49,013 - wallander.data_providers (10381) - DEBUG - Checking path: []
2016-04-14 14:02:49,014 - wallander.application (10381) - ERROR - Exception processing request
Traceback (most recent call last):
  File "/var/wallander/python/wallander/application.py", line 45, in __call__
    r=dp(environ,start_response,path)
  File "/var/wallander/python/wallander/data_providers.py", line 49, in __call__
    if path[0][0]=='_':
IndexError: list index out of range
2016-04-14 14:02:49,014 - wallander.application (10381) - ERROR - Exception processing request
Traceback (most recent call last):
  File "/var/wallander/python/wallander/application.py", line 45, in __call__
    r=dp(environ,start_response,path)
  File "/var/wallander/python/wallander/data_providers.py", line 49, in __call__
    if path[0][0]=='_':
IndexError: list index out of range
2016-04-14 14:04:13,247 - config (10413) - WARNING - Couldn't find logger 'LOG' in '<module '__main__' (built-in)>'
2016-04-14 14:04:18,875 - wallander.application (10413) - DEBUG - REQUEST_URI: stagyy
2016-04-14 14:04:18,875 - wallander.application (10413) - DEBUG - REQUEST_URI: stagyy
2016-04-14 14:04:18,877 - wallander.application (10413) - DEBUG - Data provider name: 'stagyy'
2016-04-14 14:04:18,877 - wallander.application (10413) - DEBUG - Data provider name: 'stagyy'
2016-04-14 14:04:18,878 - wallander.application (10413) - DEBUG - Data provider: <stagyy.DataProvider object at 0x7f09b5053fd0>
2016-04-14 14:04:18,878 - wallander.application (10413) - DEBUG - Data provider: <stagyy.DataProvider object at 0x7f09b5053fd0>
2016-04-14 14:04:18,879 - wallander.data_providers (10413) - DEBUG - Checking path: []
2016-04-14 14:04:18,879 - wallander.data_providers (10413) - DEBUG - Checking path: []
2016-04-14 14:04:18,880 - wallander.application (10413) - ERROR - Exception processing request
Traceback (most recent call last):
  File "/var/wallander/python/wallander/application.py", line 45, in __call__
    r=dp(environ,start_response,path)
  File "/var/wallander/python/wallander/data_providers.py", line 49, in __call__
    if path[0][0:1]=='_':
IndexError: list index out of range
2016-04-14 14:04:18,880 - wallander.application (10413) - ERROR - Exception processing request
Traceback (most recent call last):
  File "/var/wallander/python/wallander/application.py", line 45, in __call__
    r=dp(environ,start_response,path)
  File "/var/wallander/python/wallander/data_providers.py", line 49, in __call__
    if path[0][0:1]=='_':
IndexError: list index out of range
2016-04-14 14:04:22,505 - wallander.application (10413) - DEBUG - REQUEST_URI: stagyy/
2016-04-14 14:04:22,505 - wallander.application (10413) - DEBUG - REQUEST_URI: stagyy/
2016-04-14 14:04:22,506 - wallander.application (10413) - DEBUG - Data provider name: 'stagyy'
2016-04-14 14:04:22,506 - wallander.application (10413) - DEBUG - Data provider name: 'stagyy'
2016-04-14 14:04:22,506 - wallander.application (10413) - DEBUG - Data provider: <stagyy.DataProvider object at 0x7f09b5053fd0>
2016-04-14 14:04:22,506 - wallander.application (10413) - DEBUG - Data provider: <stagyy.DataProvider object at 0x7f09b5053fd0>
2016-04-14 14:04:22,506 - wallander.data_providers (10413) - DEBUG - Checking path: []
2016-04-14 14:04:22,506 - wallander.data_providers (10413) - DEBUG - Checking path: []
2016-04-14 14:04:22,507 - wallander.application (10413) - ERROR - Exception processing request
Traceback (most recent call last):
  File "/var/wallander/python/wallander/application.py", line 45, in __call__
    r=dp(environ,start_response,path)
  File "/var/wallander/python/wallander/data_providers.py", line 49, in __call__
    if path[0][0:1]=='_':
IndexError: list index out of range
2016-04-14 14:04:22,507 - wallander.application (10413) - ERROR - Exception processing request
Traceback (most recent call last):
  File "/var/wallander/python/wallander/application.py", line 45, in __call__
    r=dp(environ,start_response,path)
  File "/var/wallander/python/wallander/data_providers.py", line 49, in __call__
    if path[0][0:1]=='_':
IndexError: list index out of range
2016-04-14 14:04:52,164 - wallander.application (10413) - DEBUG - REQUEST_URI: stagyy/_
2016-04-14 14:04:52,164 - wallander.application (10413) - DEBUG - REQUEST_URI: stagyy/_
2016-04-14 14:04:52,165 - wallander.application (10413) - DEBUG - Data provider name: 'stagyy'
2016-04-14 14:04:52,165 - wallander.application (10413) - DEBUG - Data provider name: 'stagyy'
2016-04-14 14:04:52,165 - wallander.application (10413) - DEBUG - Data provider: <stagyy.DataProvider object at 0x7f09b5053fd0>
2016-04-14 14:04:52,165 - wallander.application (10413) - DEBUG - Data provider: <stagyy.DataProvider object at 0x7f09b5053fd0>
2016-04-14 14:04:52,165 - wallander.data_providers (10413) - DEBUG - Checking path: ['_']
2016-04-14 14:04:52,165 - wallander.data_providers (10413) - DEBUG - Checking path: ['_']
2016-04-14 14:06:26,352 - config (10460) - WARNING - Couldn't find logger 'LOG' in '<module '__main__' (built-in)>'
2016-04-14 14:06:33,243 - wallander.application (10460) - DEBUG - REQUEST_URI: stagyy/_icons/folder.svg
2016-04-14 14:06:33,243 - wallander.application (10460) - DEBUG - REQUEST_URI: stagyy/_icons/folder.svg
2016-04-14 14:06:33,244 - wallander.application (10460) - DEBUG - Data provider name: 'stagyy'
2016-04-14 14:06:33,244 - wallander.application (10460) - DEBUG - Data provider name: 'stagyy'
2016-04-14 14:06:33,245 - wallander.application (10460) - DEBUG - Data provider: <stagyy.DataProvider object at 0x7f6d29e3afd0>
2016-04-14 14:06:33,245 - wallander.application (10460) - DEBUG - Data provider: <stagyy.DataProvider object at 0x7f6d29e3afd0>
2016-04-14 14:06:33,245 - wallander.data_providers (10460) - DEBUG - Checking path: ['_icons', 'folder.svg']
2016-04-14 14:06:33,245 - wallander.data_providers (10460) - DEBUG - Checking path: ['_icons', 'folder.svg']
2016-04-14 14:06:33,246 - stagyy (10460) - DEBUG - Checking path: /var/wallander/data/stagyy/_icons/folder.svg
2016-04-14 14:06:33,246 - stagyy (10460) - DEBUG - Checking path: /var/wallander/data/stagyy/_icons
2016-04-14 14:06:33,246 - stagyy (10460) - DEBUG - Checking path: /var/wallander/data/stagyy
2016-04-14 14:06:33,246 - wallander.application (10460) - ERROR - Exception processing request
Traceback (most recent call last):
  File "/var/wallander/python/wallander/application.py", line 45, in __call__
    r=dp(environ,start_response,path)
  File "/var/wallander/python/wallander/data_providers.py", line 50, in __call__
    if not result and path[0][0:1]=='_':
IndexError: list index out of range
2016-04-14 14:06:33,246 - wallander.application (10460) - ERROR - Exception processing request
Traceback (most recent call last):
  File "/var/wallander/python/wallander/application.py", line 45, in __call__
    r=dp(environ,start_response,path)
  File "/var/wallander/python/wallander/data_providers.py", line 50, in __call__
    if not result and path[0][0:1]=='_':
IndexError: list index out of range
2016-04-14 14:08:27,437 - config (10498) - WARNING - Couldn't find logger 'LOG' in '<module '__main__' (built-in)>'
2016-04-14 14:08:29,978 - wallander.application (10498) - DEBUG - REQUEST_URI: stagyy/_icons/folder.svg
2016-04-14 14:08:29,978 - wallander.application (10498) - DEBUG - REQUEST_URI: stagyy/_icons/folder.svg
2016-04-14 14:08:29,981 - wallander.application (10498) - DEBUG - Data provider name: 'stagyy'
2016-04-14 14:08:29,981 - wallander.application (10498) - DEBUG - Data provider name: 'stagyy'
2016-04-14 14:08:29,982 - wallander.application (10498) - DEBUG - Data provider: <stagyy.DataProvider object at 0x7f3088884fd0>
2016-04-14 14:08:29,982 - wallander.application (10498) - DEBUG - Data provider: <stagyy.DataProvider object at 0x7f3088884fd0>
2016-04-14 14:08:29,982 - wallander.data_providers (10498) - DEBUG - Checking path: ['_icons', 'folder.svg']
2016-04-14 14:08:29,982 - wallander.data_providers (10498) - DEBUG - Checking path: ['_icons', 'folder.svg']
2016-04-14 14:08:29,982 - stagyy (10498) - DEBUG - Checking path: /var/wallander/data/stagyy/_icons/folder.svg
2016-04-14 14:08:29,982 - stagyy (10498) - DEBUG - Checking path: /var/wallander/data/stagyy/_icons
2016-04-14 14:08:29,983 - stagyy (10498) - DEBUG - Checking path: /var/wallander/data/stagyy
2016-04-14 14:08:37,289 - wallander.application (10498) - DEBUG - REQUEST_URI: stagyy
2016-04-14 14:08:37,289 - wallander.application (10498) - DEBUG - REQUEST_URI: stagyy
2016-04-14 14:08:37,290 - wallander.application (10498) - DEBUG - Data provider name: 'stagyy'
2016-04-14 14:08:37,290 - wallander.application (10498) - DEBUG - Data provider name: 'stagyy'
2016-04-14 14:08:37,290 - wallander.application (10498) - DEBUG - Data provider: <stagyy.DataProvider object at 0x7f3088884fd0>
2016-04-14 14:08:37,290 - wallander.application (10498) - DEBUG - Data provider: <stagyy.DataProvider object at 0x7f3088884fd0>
2016-04-14 14:08:37,290 - wallander.data_providers (10498) - DEBUG - Checking path: []
2016-04-14 14:08:37,290 - wallander.data_providers (10498) - DEBUG - Checking path: []
2016-04-14 14:08:37,291 - stagyy (10498) - DEBUG - Checking path: /var/wallander/data/stagyy
2016-04-14 14:08:37,291 - stagyy (10498) - DEBUG - Root
2016-04-14 14:08:43,397 - wallander.application (10498) - DEBUG - REQUEST_URI: stagyy/psd/
2016-04-14 14:08:43,397 - wallander.application (10498) - DEBUG - REQUEST_URI: stagyy/psd/
2016-04-14 14:08:43,397 - wallander.application (10498) - DEBUG - Data provider name: 'stagyy'
2016-04-14 14:08:43,397 - wallander.application (10498) - DEBUG - Data provider name: 'stagyy'
2016-04-14 14:08:43,398 - wallander.application (10498) - DEBUG - Data provider: <stagyy.DataProvider object at 0x7f3088884fd0>
2016-04-14 14:08:43,398 - wallander.application (10498) - DEBUG - Data provider: <stagyy.DataProvider object at 0x7f3088884fd0>
2016-04-14 14:08:43,398 - wallander.data_providers (10498) - DEBUG - Checking path: ['psd']
2016-04-14 14:08:43,398 - wallander.data_providers (10498) - DEBUG - Checking path: ['psd']
2016-04-14 14:08:43,398 - stagyy (10498) - DEBUG - Checking path: /var/wallander/data/stagyy/psd
2016-04-14 14:08:49,183 - wallander.application (10498) - DEBUG - REQUEST_URI: stagyy/psd/psd03
2016-04-14 14:08:49,183 - wallander.application (10498) - DEBUG - REQUEST_URI: stagyy/psd/psd03
2016-04-14 14:08:49,184 - wallander.application (10498) - DEBUG - Data provider name: 'stagyy'
2016-04-14 14:08:49,184 - wallander.application (10498) - DEBUG - Data provider name: 'stagyy'
2016-04-14 14:08:49,184 - wallander.application (10498) - DEBUG - Data provider: <stagyy.DataProvider object at 0x7f3088884fd0>
2016-04-14 14:08:49,184 - wallander.application (10498) - DEBUG - Data provider: <stagyy.DataProvider object at 0x7f3088884fd0>
2016-04-14 14:08:49,185 - wallander.data_providers (10498) - DEBUG - Checking path: ['psd', 'psd03']
2016-04-14 14:08:49,185 - wallander.data_providers (10498) - DEBUG - Checking path: ['psd', 'psd03']
2016-04-14 14:08:49,185 - stagyy (10498) - DEBUG - Checking path: /var/wallander/data/stagyy/psd/psd03
2016-04-14 14:09:05,668 - wallander.application (10498) - DEBUG - REQUEST_URI: stagyy/psd/psd03/psd_00017
2016-04-14 14:09:05,668 - wallander.application (10498) - DEBUG - REQUEST_URI: stagyy/psd/psd03/psd_00017
2016-04-14 14:09:05,669 - wallander.application (10498) - DEBUG - Data provider name: 'stagyy'
2016-04-14 14:09:05,669 - wallander.application (10498) - DEBUG - Data provider name: 'stagyy'
2016-04-14 14:09:05,670 - wallander.application (10498) - DEBUG - Data provider: <stagyy.DataProvider object at 0x7f3088884fd0>
2016-04-14 14:09:05,670 - wallander.application (10498) - DEBUG - Data provider: <stagyy.DataProvider object at 0x7f3088884fd0>
2016-04-14 14:09:05,670 - wallander.data_providers (10498) - DEBUG - Checking path: ['psd', 'psd03', 'psd_00017']
2016-04-14 14:09:05,670 - wallander.data_providers (10498) - DEBUG - Checking path: ['psd', 'psd03', 'psd_00017']
2016-04-14 14:09:05,670 - stagyy (10498) - DEBUG - Checking path: /var/wallander/data/stagyy/psd/psd03/psd_00017
2016-04-14 14:09:05,671 - wallander.application (10498) - ERROR - Exception processing request
Traceback (most recent call last):
  File "/var/wallander/python/wallander/application.py", line 49, in __call__
    return response.respond_ok(r,start_response)
  File "/var/wallander/python/wallander/response.py", line 64, in respond_ok
    return iter([json.dumps(v)])
  File "/usr/lib/python2.7/json/__init__.py", line 243, in dumps
    return _default_encoder.encode(obj)
  File "/usr/lib/python2.7/json/encoder.py", line 207, in encode
    chunks = self.iterencode(o, _one_shot=True)
  File "/usr/lib/python2.7/json/encoder.py", line 270, in iterencode
    return _iterencode(o, 0)
  File "/var/wallander/python/wallander/make_json_serialize_objects.py", line 10, in _default
    return obj.to_json()
  File "/var/wallander/data_providers/stagyy/__init__.py", line 97, in to_json
    "name": os.path.basename(self.directory),
AttributeError: 'H5DataSourceFolder' object has no attribute 'directory'
2016-04-14 14:09:05,671 - wallander.application (10498) - ERROR - Exception processing request
Traceback (most recent call last):
  File "/var/wallander/python/wallander/application.py", line 49, in __call__
    return response.respond_ok(r,start_response)
  File "/var/wallander/python/wallander/response.py", line 64, in respond_ok
    return iter([json.dumps(v)])
  File "/usr/lib/python2.7/json/__init__.py", line 243, in dumps
    return _default_encoder.encode(obj)
  File "/usr/lib/python2.7/json/encoder.py", line 207, in encode
    chunks = self.iterencode(o, _one_shot=True)
  File "/usr/lib/python2.7/json/encoder.py", line 270, in iterencode
    return _iterencode(o, 0)
  File "/var/wallander/python/wallander/make_json_serialize_objects.py", line 10, in _default
    return obj.to_json()
  File "/var/wallander/data_providers/stagyy/__init__.py", line 97, in to_json
    "name": os.path.basename(self.directory),
AttributeError: 'H5DataSourceFolder' object has no attribute 'directory'
2016-04-14 14:09:10,138 - wallander.application (10498) - DEBUG - REQUEST_URI: stagyy/psd/psd03/psd_00017/
2016-04-14 14:09:10,138 - wallander.application (10498) - DEBUG - REQUEST_URI: stagyy/psd/psd03/psd_00017/
2016-04-14 14:09:10,139 - wallander.application (10498) - DEBUG - Data provider name: 'stagyy'
2016-04-14 14:09:10,139 - wallander.application (10498) - DEBUG - Data provider name: 'stagyy'
2016-04-14 14:09:10,141 - wallander.application (10498) - DEBUG - Data provider: <stagyy.DataProvider object at 0x7f3088884fd0>
2016-04-14 14:09:10,141 - wallander.application (10498) - DEBUG - Data provider: <stagyy.DataProvider object at 0x7f3088884fd0>
2016-04-14 14:09:10,142 - wallander.data_providers (10498) - DEBUG - Checking path: ['psd', 'psd03', 'psd_00017']
2016-04-14 14:09:10,142 - wallander.data_providers (10498) - DEBUG - Checking path: ['psd', 'psd03', 'psd_00017']
2016-04-14 14:09:10,142 - stagyy (10498) - DEBUG - Checking path: /var/wallander/data/stagyy/psd/psd03/psd_00017
2016-04-14 14:09:10,143 - wallander.application (10498) - ERROR - Exception processing request
Traceback (most recent call last):
  File "/var/wallander/python/wallander/application.py", line 49, in __call__
    return response.respond_ok(r,start_response)
  File "/var/wallander/python/wallander/response.py", line 64, in respond_ok
    return iter([json.dumps(v)])
  File "/usr/lib/python2.7/json/__init__.py", line 243, in dumps
    return _default_encoder.encode(obj)
  File "/usr/lib/python2.7/json/encoder.py", line 207, in encode
    chunks = self.iterencode(o, _one_shot=True)
  File "/usr/lib/python2.7/json/encoder.py", line 270, in iterencode
    return _iterencode(o, 0)
  File "/var/wallander/python/wallander/make_json_serialize_objects.py", line 10, in _default
    return obj.to_json()
  File "/var/wallander/data_providers/stagyy/__init__.py", line 97, in to_json
    "name": os.path.basename(self.directory),
AttributeError: 'H5DataSourceFolder' object has no attribute 'directory'
2016-04-14 14:09:10,143 - wallander.application (10498) - ERROR - Exception processing request
Traceback (most recent call last):
  File "/var/wallander/python/wallander/application.py", line 49, in __call__
    return response.respond_ok(r,start_response)
  File "/var/wallander/python/wallander/response.py", line 64, in respond_ok
    return iter([json.dumps(v)])
  File "/usr/lib/python2.7/json/__init__.py", line 243, in dumps
    return _default_encoder.encode(obj)
  File "/usr/lib/python2.7/json/encoder.py", line 207, in encode
    chunks = self.iterencode(o, _one_shot=True)
  File "/usr/lib/python2.7/json/encoder.py", line 270, in iterencode
    return _iterencode(o, 0)
  File "/var/wallander/python/wallander/make_json_serialize_objects.py", line 10, in _default
    return obj.to_json()
  File "/var/wallander/data_providers/stagyy/__init__.py", line 97, in to_json
    "name": os.path.basename(self.directory),
AttributeError: 'H5DataSourceFolder' object has no attribute 'directory'
2016-04-14 14:10:11,370 - config (10545) - WARNING - Couldn't find logger 'LOG' in '<module '__main__' (built-in)>'
2016-04-14 14:10:13,375 - wallander.application (10545) - DEBUG - REQUEST_URI: stagyy/psd/psd03/psd_00017/
2016-04-14 14:10:13,375 - wallander.application (10545) - DEBUG - REQUEST_URI: stagyy/psd/psd03/psd_00017/
2016-04-14 14:10:13,377 - wallander.application (10545) - DEBUG - Data provider name: 'stagyy'
2016-04-14 14:10:13,377 - wallander.application (10545) - DEBUG - Data provider name: 'stagyy'
2016-04-14 14:10:13,378 - wallander.application (10545) - DEBUG - Data provider: <stagyy.DataProvider object at 0x7fc052421ed0>
2016-04-14 14:10:13,378 - wallander.application (10545) - DEBUG - Data provider: <stagyy.DataProvider object at 0x7fc052421ed0>
2016-04-14 14:10:13,378 - wallander.data_providers (10545) - DEBUG - Checking path: ['psd', 'psd03', 'psd_00017']
2016-04-14 14:10:13,378 - wallander.data_providers (10545) - DEBUG - Checking path: ['psd', 'psd03', 'psd_00017']
2016-04-14 14:10:13,378 - stagyy (10545) - DEBUG - Checking path: /var/wallander/data/stagyy/psd/psd03/psd_00017
2016-04-14 14:10:13,379 - wallander.application (10545) - ERROR - Exception processing request
Traceback (most recent call last):
  File "/var/wallander/python/wallander/application.py", line 49, in __call__
    return response.respond_ok(r,start_response)
  File "/var/wallander/python/wallander/response.py", line 64, in respond_ok
    return iter([json.dumps(v)])
  File "/usr/lib/python2.7/json/__init__.py", line 243, in dumps
    return _default_encoder.encode(obj)
  File "/usr/lib/python2.7/json/encoder.py", line 207, in encode
    chunks = self.iterencode(o, _one_shot=True)
  File "/usr/lib/python2.7/json/encoder.py", line 270, in iterencode
    return _iterencode(o, 0)
  File "/var/wallander/python/wallander/make_json_serialize_objects.py", line 10, in _default
    return obj.to_json()
  File "/var/wallander/data_providers/stagyy/__init__.py", line 101, in to_json
    json["children"]=self.children()
  File "/var/wallander/data_providers/stagyy/__init__.py", line 106, in children
    for f in os.listdir(self.file):
AttributeError: 'H5DataSourceFolder' object has no attribute 'file'
2016-04-14 14:10:13,379 - wallander.application (10545) - ERROR - Exception processing request
Traceback (most recent call last):
  File "/var/wallander/python/wallander/application.py", line 49, in __call__
    return response.respond_ok(r,start_response)
  File "/var/wallander/python/wallander/response.py", line 64, in respond_ok
    return iter([json.dumps(v)])
  File "/usr/lib/python2.7/json/__init__.py", line 243, in dumps
    return _default_encoder.encode(obj)
  File "/usr/lib/python2.7/json/encoder.py", line 207, in encode
    chunks = self.iterencode(o, _one_shot=True)
  File "/usr/lib/python2.7/json/encoder.py", line 270, in iterencode
    return _iterencode(o, 0)
  File "/var/wallander/python/wallander/make_json_serialize_objects.py", line 10, in _default
    return obj.to_json()
  File "/var/wallander/data_providers/stagyy/__init__.py", line 101, in to_json
    json["children"]=self.children()
  File "/var/wallander/data_providers/stagyy/__init__.py", line 106, in children
    for f in os.listdir(self.file):
AttributeError: 'H5DataSourceFolder' object has no attribute 'file'
2016-04-14 14:10:39,869 - wallander.application (10545) - DEBUG - REQUEST_URI: stagyy/psd/psd03/psd_00017/
2016-04-14 14:10:39,869 - wallander.application (10545) - DEBUG - REQUEST_URI: stagyy/psd/psd03/psd_00017/
2016-04-14 14:10:39,869 - wallander.application (10545) - DEBUG - Data provider name: 'stagyy'
2016-04-14 14:10:39,869 - wallander.application (10545) - DEBUG - Data provider name: 'stagyy'
2016-04-14 14:10:39,870 - wallander.application (10545) - DEBUG - Data provider: <stagyy.DataProvider object at 0x7fc052421ed0>
2016-04-14 14:10:39,870 - wallander.application (10545) - DEBUG - Data provider: <stagyy.DataProvider object at 0x7fc052421ed0>
2016-04-14 14:10:39,870 - wallander.data_providers (10545) - DEBUG - Checking path: ['psd', 'psd03', 'psd_00017']
2016-04-14 14:10:39,870 - wallander.data_providers (10545) - DEBUG - Checking path: ['psd', 'psd03', 'psd_00017']
2016-04-14 14:10:39,871 - stagyy (10545) - DEBUG - Checking path: /var/wallander/data/stagyy/psd/psd03/psd_00017
2016-04-14 14:10:39,871 - wallander.application (10545) - ERROR - Exception processing request
Traceback (most recent call last):
  File "/var/wallander/python/wallander/application.py", line 49, in __call__
    return response.respond_ok(r,start_response)
  File "/var/wallander/python/wallander/response.py", line 64, in respond_ok
    return iter([json.dumps(v)])
  File "/usr/lib/python2.7/json/__init__.py", line 243, in dumps
    return _default_encoder.encode(obj)
  File "/usr/lib/python2.7/json/encoder.py", line 207, in encode
    chunks = self.iterencode(o, _one_shot=True)
  File "/usr/lib/python2.7/json/encoder.py", line 270, in iterencode
    return _iterencode(o, 0)
  File "/var/wallander/python/wallander/make_json_serialize_objects.py", line 10, in _default
    return obj.to_json()
  File "/var/wallander/data_providers/stagyy/__init__.py", line 101, in to_json
    json["children"]=self.children()
  File "/var/wallander/data_providers/stagyy/__init__.py", line 106, in children
    for f in os.listdir(self.directory):
AttributeError: 'H5DataSourceFolder' object has no attribute 'file'
2016-04-14 14:10:39,871 - wallander.application (10545) - ERROR - Exception processing request
Traceback (most recent call last):
  File "/var/wallander/python/wallander/application.py", line 49, in __call__
    return response.respond_ok(r,start_response)
  File "/var/wallander/python/wallander/response.py", line 64, in respond_ok
    return iter([json.dumps(v)])
  File "/usr/lib/python2.7/json/__init__.py", line 243, in dumps
    return _default_encoder.encode(obj)
  File "/usr/lib/python2.7/json/encoder.py", line 207, in encode
    chunks = self.iterencode(o, _one_shot=True)
  File "/usr/lib/python2.7/json/encoder.py", line 270, in iterencode
    return _iterencode(o, 0)
  File "/var/wallander/python/wallander/make_json_serialize_objects.py", line 10, in _default
    return obj.to_json()
  File "/var/wallander/data_providers/stagyy/__init__.py", line 101, in to_json
    json["children"]=self.children()
  File "/var/wallander/data_providers/stagyy/__init__.py", line 106, in children
    for f in os.listdir(self.directory):
AttributeError: 'H5DataSourceFolder' object has no attribute 'file'
2016-04-14 14:10:53,592 - config (10574) - WARNING - Couldn't find logger 'LOG' in '<module '__main__' (built-in)>'
2016-04-14 14:10:53,597 - wallander.cache (10574) - DEBUG - CacheInvalidationThread started
2016-04-14 14:10:53,597 - wallander.cache (10574) - DEBUG - CacheInvalidationThread started
2016-04-14 14:10:53,598 - wallander.cache (10574) - DEBUG - Checking cache items...
2016-04-14 14:10:53,598 - wallander.cache (10574) - DEBUG - Checking cache items...
2016-04-14 14:10:55,783 - wallander.application (10574) - DEBUG - REQUEST_URI: stagyy/psd/psd03/psd_00017/
2016-04-14 14:10:55,783 - wallander.application (10574) - DEBUG - REQUEST_URI: stagyy/psd/psd03/psd_00017/
2016-04-14 14:10:55,784 - wallander.application (10574) - DEBUG - Data provider name: 'stagyy'
2016-04-14 14:10:55,784 - wallander.application (10574) - DEBUG - Data provider name: 'stagyy'
2016-04-14 14:10:55,784 - wallander.application (10574) - DEBUG - Data provider: <stagyy.DataProvider object at 0x7f9cc1736ed0>
2016-04-14 14:10:55,784 - wallander.application (10574) - DEBUG - Data provider: <stagyy.DataProvider object at 0x7f9cc1736ed0>
2016-04-14 14:10:55,785 - wallander.data_providers (10574) - DEBUG - Checking path: ['psd', 'psd03', 'psd_00017']
2016-04-14 14:10:55,785 - wallander.data_providers (10574) - DEBUG - Checking path: ['psd', 'psd03', 'psd_00017']
2016-04-14 14:10:55,785 - stagyy (10574) - DEBUG - Checking path: /var/wallander/data/stagyy/psd/psd03/psd_00017
2016-04-14 14:15:53,660 - wallander.cache (10574) - DEBUG - Checking cache items...
2016-04-14 14:15:53,660 - wallander.cache (10574) - DEBUG - Checking cache items...
2016-04-14 14:16:42,711 - config (10795) - WARNING - Couldn't find logger 'LOG' in '<module '__main__' (built-in)>'
2016-04-14 14:16:45,886 - wallander.application (10795) - DEBUG - REQUEST_URI: stagyy/psd/psd03/psd_00017/
2016-04-14 14:16:45,886 - wallander.application (10795) - DEBUG - REQUEST_URI: stagyy/psd/psd03/psd_00017/
2016-04-14 14:16:45,888 - wallander.application (10795) - DEBUG - Data provider name: 'stagyy'
2016-04-14 14:16:45,888 - wallander.application (10795) - DEBUG - Data provider name: 'stagyy'
2016-04-14 14:16:45,890 - wallander.application (10795) - DEBUG - Data provider: <stagyy.DataProvider object at 0x7fcb5ddbaf10>
2016-04-14 14:16:45,890 - wallander.application (10795) - DEBUG - Data provider: <stagyy.DataProvider object at 0x7fcb5ddbaf10>
2016-04-14 14:16:45,891 - wallander.data_providers (10795) - DEBUG - Checking path: ['psd', 'psd03', 'psd_00017']
2016-04-14 14:16:45,891 - wallander.data_providers (10795) - DEBUG - Checking path: ['psd', 'psd03', 'psd_00017']
2016-04-14 14:16:45,893 - stagyy (10795) - DEBUG - Checking path: /var/wallander/data/stagyy/psd/psd03/psd_00017
2016-04-14 14:18:21,099 - wallander.application (10795) - DEBUG - REQUEST_URI: stagyy
2016-04-14 14:18:21,099 - wallander.application (10795) - DEBUG - REQUEST_URI: stagyy
2016-04-14 14:18:21,100 - wallander.application (10795) - DEBUG - Data provider name: 'stagyy'
2016-04-14 14:18:21,100 - wallander.application (10795) - DEBUG - Data provider name: 'stagyy'
2016-04-14 14:18:21,101 - wallander.application (10795) - DEBUG - Data provider: <stagyy.DataProvider object at 0x7fcb5ddbaf10>
2016-04-14 14:18:21,101 - wallander.application (10795) - DEBUG - Data provider: <stagyy.DataProvider object at 0x7fcb5ddbaf10>
2016-04-14 14:18:21,101 - wallander.data_providers (10795) - DEBUG - Checking path: []
2016-04-14 14:18:21,101 - wallander.data_providers (10795) - DEBUG - Checking path: []
2016-04-14 14:18:21,101 - stagyy (10795) - DEBUG - Checking path: /var/wallander/data/stagyy
2016-04-14 14:18:21,101 - stagyy (10795) - DEBUG - Root
2016-04-14 14:18:36,171 - wallander.application (10795) - DEBUG - REQUEST_URI: stagyy/psd/psd03
2016-04-14 14:18:36,171 - wallander.application (10795) - DEBUG - REQUEST_URI: stagyy/psd/psd03
2016-04-14 14:18:36,172 - wallander.application (10795) - DEBUG - Data provider name: 'stagyy'
2016-04-14 14:18:36,172 - wallander.application (10795) - DEBUG - Data provider name: 'stagyy'
2016-04-14 14:18:36,173 - wallander.application (10795) - DEBUG - Data provider: <stagyy.DataProvider object at 0x7fcb5ddbaf10>
2016-04-14 14:18:36,173 - wallander.application (10795) - DEBUG - Data provider: <stagyy.DataProvider object at 0x7fcb5ddbaf10>
2016-04-14 14:18:36,173 - wallander.data_providers (10795) - DEBUG - Checking path: ['psd', 'psd03']
2016-04-14 14:18:36,173 - wallander.data_providers (10795) - DEBUG - Checking path: ['psd', 'psd03']
2016-04-14 14:18:36,173 - stagyy (10795) - DEBUG - Checking path: /var/wallander/data/stagyy/psd/psd03
2016-04-14 14:19:12,443 - config (10838) - WARNING - Couldn't find logger 'LOG' in '<module '__main__' (built-in)>'
2016-04-14 14:19:14,753 - wallander.application (10838) - DEBUG - REQUEST_URI: stagyy/psd/psd03
2016-04-14 14:19:14,753 - wallander.application (10838) - DEBUG - REQUEST_URI: stagyy/psd/psd03
2016-04-14 14:19:14,754 - wallander.application (10838) - DEBUG - Data provider name: 'stagyy'
2016-04-14 14:19:14,754 - wallander.application (10838) - DEBUG - Data provider name: 'stagyy'
2016-04-14 14:19:14,754 - wallander.application (10838) - DEBUG - Data provider: <stagyy.DataProvider object at 0x7fbbe2b55ed0>
2016-04-14 14:19:14,754 - wallander.application (10838) - DEBUG - Data provider: <stagyy.DataProvider object at 0x7fbbe2b55ed0>
2016-04-14 14:19:14,754 - wallander.data_providers (10838) - DEBUG - Checking path: ['psd', 'psd03']
2016-04-14 14:19:14,754 - wallander.data_providers (10838) - DEBUG - Checking path: ['psd', 'psd03']
2016-04-14 14:19:14,755 - stagyy (10838) - DEBUG - Checking path: /var/wallander/data/stagyy/psd/psd03
2016-04-14 14:19:31,552 - wallander.application (10838) - DEBUG - REQUEST_URI: stagyy/_icons/folder
2016-04-14 14:19:31,552 - wallander.application (10838) - DEBUG - REQUEST_URI: stagyy/_icons/folder
2016-04-14 14:19:31,553 - wallander.application (10838) - DEBUG - Data provider name: 'stagyy'
2016-04-14 14:19:31,553 - wallander.application (10838) - DEBUG - Data provider name: 'stagyy'
2016-04-14 14:19:31,553 - wallander.application (10838) - DEBUG - Data provider: <stagyy.DataProvider object at 0x7fbbe2b55ed0>
2016-04-14 14:19:31,553 - wallander.application (10838) - DEBUG - Data provider: <stagyy.DataProvider object at 0x7fbbe2b55ed0>
2016-04-14 14:19:31,553 - wallander.data_providers (10838) - DEBUG - Checking path: ['_icons', 'folder']
2016-04-14 14:19:31,553 - wallander.data_providers (10838) - DEBUG - Checking path: ['_icons', 'folder']
2016-04-14 14:19:31,553 - stagyy (10838) - DEBUG - Checking path: /var/wallander/data/stagyy/_icons/folder
2016-04-14 14:19:31,554 - stagyy (10838) - DEBUG - Checking path: /var/wallander/data/stagyy/_icons
2016-04-14 14:19:31,554 - stagyy (10838) - DEBUG - Checking path: /var/wallander/data/stagyy
2016-04-14 14:19:31,554 - wallander.application (10838) - ERROR - Exception processing request
Traceback (most recent call last):
  File "/var/wallander/python/wallander/application.py", line 45, in __call__
    r=dp(environ,start_response,path)
  File "/var/wallander/python/wallander/data_providers.py", line 53, in __call__
    result=f(environ,start_response,path[1:])
  File "/var/wallander/python/wallander/data_providers.py", line 62, in _icons
    return resource_string('wallander._icons',path[0])
  File "/usr/lib/python2.7/dist-packages/pkg_resources/__init__.py", line 1173, in resource_string
    self, resource_name
  File "/usr/lib/python2.7/dist-packages/pkg_resources/__init__.py", line 1605, in get_resource_string
    return self._get(self._fn(self.module_path, resource_name))
  File "/usr/lib/python2.7/dist-packages/pkg_resources/__init__.py", line 1728, in _get
    with open(path, 'rb') as stream:
IOError: [Errno 2] No such file or directory: '/var/wallander/python/wallander/_icons/folder'
2016-04-14 14:19:31,554 - wallander.application (10838) - ERROR - Exception processing request
Traceback (most recent call last):
  File "/var/wallander/python/wallander/application.py", line 45, in __call__
    r=dp(environ,start_response,path)
  File "/var/wallander/python/wallander/data_providers.py", line 53, in __call__
    result=f(environ,start_response,path[1:])
  File "/var/wallander/python/wallander/data_providers.py", line 62, in _icons
    return resource_string('wallander._icons',path[0])
  File "/usr/lib/python2.7/dist-packages/pkg_resources/__init__.py", line 1173, in resource_string
    self, resource_name
  File "/usr/lib/python2.7/dist-packages/pkg_resources/__init__.py", line 1605, in get_resource_string
    return self._get(self._fn(self.module_path, resource_name))
  File "/usr/lib/python2.7/dist-packages/pkg_resources/__init__.py", line 1728, in _get
    with open(path, 'rb') as stream:
IOError: [Errno 2] No such file or directory: '/var/wallander/python/wallander/_icons/folder'
2016-04-14 14:19:36,471 - wallander.application (10838) - DEBUG - REQUEST_URI: stagyy/_icons/folder.svg
2016-04-14 14:19:36,471 - wallander.application (10838) - DEBUG - REQUEST_URI: stagyy/_icons/folder.svg
2016-04-14 14:19:36,472 - wallander.application (10838) - DEBUG - Data provider name: 'stagyy'
2016-04-14 14:19:36,472 - wallander.application (10838) - DEBUG - Data provider name: 'stagyy'
2016-04-14 14:19:36,472 - wallander.application (10838) - DEBUG - Data provider: <stagyy.DataProvider object at 0x7fbbe2b55ed0>
2016-04-14 14:19:36,472 - wallander.application (10838) - DEBUG - Data provider: <stagyy.DataProvider object at 0x7fbbe2b55ed0>
2016-04-14 14:19:36,472 - wallander.data_providers (10838) - DEBUG - Checking path: ['_icons', 'folder.svg']
2016-04-14 14:19:36,472 - wallander.data_providers (10838) - DEBUG - Checking path: ['_icons', 'folder.svg']
2016-04-14 14:19:36,473 - stagyy (10838) - DEBUG - Checking path: /var/wallander/data/stagyy/_icons/folder.svg
2016-04-14 14:19:36,473 - stagyy (10838) - DEBUG - Checking path: /var/wallander/data/stagyy/_icons
2016-04-14 14:19:36,473 - stagyy (10838) - DEBUG - Checking path: /var/wallander/data/stagyy
2016-04-14 14:20:00,330 - wallander.application (10838) - DEBUG - REQUEST_URI: stagyy/psd/psd03
2016-04-14 14:20:00,330 - wallander.application (10838) - DEBUG - REQUEST_URI: stagyy/psd/psd03
2016-04-14 14:20:00,331 - wallander.application (10838) - DEBUG - Data provider name: 'stagyy'
2016-04-14 14:20:00,331 - wallander.application (10838) - DEBUG - Data provider name: 'stagyy'
2016-04-14 14:20:00,331 - wallander.application (10838) - DEBUG - Data provider: <stagyy.DataProvider object at 0x7fbbe2b55ed0>
2016-04-14 14:20:00,331 - wallander.application (10838) - DEBUG - Data provider: <stagyy.DataProvider object at 0x7fbbe2b55ed0>
2016-04-14 14:20:00,332 - wallander.data_providers (10838) - DEBUG - Checking path: ['psd', 'psd03']
2016-04-14 14:20:00,332 - wallander.data_providers (10838) - DEBUG - Checking path: ['psd', 'psd03']
2016-04-14 14:20:00,332 - stagyy (10838) - DEBUG - Checking path: /var/wallander/data/stagyy/psd/psd03
2016-04-14 14:20:09,403 - wallander.application (10838) - DEBUG - REQUEST_URI: stagyy/psd/psd03/psd_00017
2016-04-14 14:20:09,403 - wallander.application (10838) - DEBUG - REQUEST_URI: stagyy/psd/psd03/psd_00017
2016-04-14 14:20:09,403 - wallander.application (10838) - DEBUG - Data provider name: 'stagyy'
2016-04-14 14:20:09,403 - wallander.application (10838) - DEBUG - Data provider name: 'stagyy'
2016-04-14 14:20:09,404 - wallander.application (10838) - DEBUG - Data provider: <stagyy.DataProvider object at 0x7fbbe2b55ed0>
2016-04-14 14:20:09,404 - wallander.application (10838) - DEBUG - Data provider: <stagyy.DataProvider object at 0x7fbbe2b55ed0>
2016-04-14 14:20:09,404 - wallander.data_providers (10838) - DEBUG - Checking path: ['psd', 'psd03', 'psd_00017']
2016-04-14 14:20:09,404 - wallander.data_providers (10838) - DEBUG - Checking path: ['psd', 'psd03', 'psd_00017']
2016-04-14 14:20:09,404 - stagyy (10838) - DEBUG - Checking path: /var/wallander/data/stagyy/psd/psd03/psd_00017
2016-04-14 14:23:00,813 - wallander.application (10838) - DEBUG - REQUEST_URI: /stagyy/psd/psd03/psd_00017/
2016-04-14 14:23:00,813 - wallander.application (10838) - DEBUG - REQUEST_URI: /stagyy/psd/psd03/psd_00017/
2016-04-14 14:23:00,815 - wallander.application (10838) - DEBUG - Data provider name: 'stagyy'
2016-04-14 14:23:00,815 - wallander.application (10838) - DEBUG - Data provider name: 'stagyy'
2016-04-14 14:23:00,816 - wallander.application (10838) - DEBUG - Data provider: <stagyy.DataProvider object at 0x7fbbe2b55ed0>
2016-04-14 14:23:00,816 - wallander.application (10838) - DEBUG - Data provider: <stagyy.DataProvider object at 0x7fbbe2b55ed0>
2016-04-14 14:23:00,816 - wallander.data_providers (10838) - DEBUG - Checking path: ['psd', 'psd03', 'psd_00017']
2016-04-14 14:23:00,816 - wallander.data_providers (10838) - DEBUG - Checking path: ['psd', 'psd03', 'psd_00017']
2016-04-14 14:23:00,817 - stagyy (10838) - DEBUG - Checking path: /var/wallander/data/stagyy/psd/psd03/psd_00017
2016-04-14 14:24:12,522 - wallander.cache (10838) - DEBUG - Checking cache items...
2016-04-14 14:24:12,522 - wallander.cache (10838) - DEBUG - Checking cache items...
2016-04-14 14:25:04,154 - wallander.application (10838) - DEBUG - REQUEST_URI: /stagyy/psd/psd03/psd_00017/
2016-04-14 14:25:04,154 - wallander.application (10838) - DEBUG - REQUEST_URI: /stagyy/psd/psd03/psd_00017/
2016-04-14 14:25:04,155 - wallander.application (10838) - DEBUG - Data provider name: 'stagyy'
2016-04-14 14:25:04,155 - wallander.application (10838) - DEBUG - Data provider name: 'stagyy'
2016-04-14 14:25:04,155 - wallander.application (10838) - DEBUG - Data provider: <stagyy.DataProvider object at 0x7fbbe2b55ed0>
2016-04-14 14:25:04,155 - wallander.application (10838) - DEBUG - Data provider: <stagyy.DataProvider object at 0x7fbbe2b55ed0>
2016-04-14 14:25:04,155 - wallander.data_providers (10838) - DEBUG - Checking path: ['psd', 'psd03', 'psd_00017']
2016-04-14 14:25:04,155 - wallander.data_providers (10838) - DEBUG - Checking path: ['psd', 'psd03', 'psd_00017']
2016-04-14 14:25:04,156 - stagyy (10838) - DEBUG - Checking path: /var/wallander/data/stagyy/psd/psd03/psd_00017
